<?xml version="1.0"?>
<robot name="dummy_bot">
    <link name="link0">
        <visual>
        <geometry>
            <cylinder length="1" radius="0.05"/>
        </geometry>
        <origin rpy="0 0 0" xyz="0 0 0.5"/>
        </visual>
    </link>

    <link name="link1">
        <visual>
        <geometry>
            <cylinder length="1" radius="0.05"/>
        </geometry>
        <origin rpy="0 0 0" xyz="0 0 0.5"/>
        </visual>
    </link>

    <joint name="joint1" type="continuous">
        <parent link="link0"/>
        <child link="link1"/>
        <origin rpy="0 0 0" xyz="0 0 1"/>
    </joint>
</robot>
