    <mujoco model="dummy">
    <include file="../common.xml" />

    <compiler angle="radian" coordinate="local"/>
    <option timestep="0.001" gravity="0 0 -9.81"/>

    <visual>
        <map znear="0.01" zfar="50"/>
    </visual>

    <!-- Must collision filter second link from static first link -->
    <contact>
        <exclude name="exclude_link0_link1" body1="link0" body2="link1"/>
    </contact>

    <worldbody>
        <!-- Settings  -->
        <geom name="floor" type="plane" size="5 5 0.1" material="blue_grid"/>
        <light name="light" pos="0 0 3" dir="0 0 -1" diffuse="1 1 1" specular="0.3 0.3 0.3"/>

        <!-- Robot -->
        <body name="link0" pos="0 0 0">
            <geom type="cylinder" fromto="0 0 0 0 0 1" size="0.05"/>
            <body name="link1" pos="0 0 1">
                <geom type="cylinder" fromto="0 0 0 0 0 1" size="0.05"/>
                <joint name="joint1" type="hinge" pos="0 0 0" axis="0 1 0" range="-1.5708 1.5708"/>
                <site name="imu_site" pos="0 0 1" euler="0 0 0" size="0.001"/>
            </body>
        </body>
    </worldbody>

    <!-- Actuators -->
    <actuator>
        <position joint="joint1" ctrlrange="-1.5708 1.5708" kp="1000.0" kv="100.0"/>
    </actuator>

    <!-- Sensors -->
    <sensor>
        <!-- Joint sensors -->
        <jointpos name="joint_pos" joint="joint1"/>
        <jointvel name="joint_vel" joint="joint1"/>

        <!-- IMU -->
        <accelerometer name="tip_acc_sensor" site="imu_site"/>
        <gyro name="tip_gyro_sensor" site="imu_site"/>
        <framequat name="tip_frame_sensor" objtype="site" objname="imu_site"/>
    </sensor>
</mujoco>
