<!-- Pulled from the unitree_ros repo on 10/18/2024 then modified.
Position and velocity actuators added. -->
<mujoco model="g1_29dof_with_hand">
  <compiler angle="radian" meshdir="../meshes"/>

  <!-- TODO: Tune the impratio -->
  <option cone="elliptic" impratio="100" integrator="implicitfast" timestep="0.001"/>
  <!-- <option cone="elliptic" impratio="100" integrator="implicitfast" timestep="0.0005"/> -->
  <!-- <option cone="pyramidal" integrator="implicitfast" timestep="0.0005"/> -->

  <!-- Defaults -->
  <default>
    <!-- ############## -->
    <!--   Leg Gains    -->
    <!-- ############## -->
    <!-- Hip Pitch -->
    <default class="hip_pitch_pos">
      <position kp="240" ctrllimited="false"/>
      <!-- <position kp="0" ctrllimited="false"/> -->
    </default>
    <default class="hip_pitch_vel">
      <position kv="4" ctrllimited="false"/>
      <!-- <position kv="0" ctrllimited="false"/> -->
    </default>

    <!-- Hip Roll -->
    <default class="hip_roll_pos">
      <position kp="160" ctrllimited="false"/>
      <!-- <position kp="0" ctrllimited="false"/> -->
    </default>
    <default class="hip_roll_vel">
      <position kv="3" ctrllimited="false"/>
      <!-- <position kv="0" ctrllimited="false"/> -->
    </default>

    <!-- Hip Yaw -->
    <default class="hip_yaw_pos">
      <position kp="120" ctrllimited="false"/>
      <!-- <position kp="0" ctrllimited="false"/> -->
    </default>
    <default class="hip_yaw_vel">
      <position kv="2" ctrllimited="false"/>
      <!-- <position kv="0" ctrllimited="false"/> -->
    </default>

    <!-- Knee -->
    <default class="knee_pos">
      <position kp="270" ctrllimited="false"/>
      <!-- 270 -->
      <!-- <position kp="0" ctrllimited="false"/> -->
    </default>
    <default class="knee_vel">
      <position kv="4" ctrllimited="false"/>
      <!-- 4 -->
      <!-- <position kv="0" ctrllimited="false"/> -->
    </default>

    <!-- Ankle Pitch -->
    <default class="ankle_pitch_pos">
      <position kp="90" ctrllimited="false"/>
      <!-- <position kp="0" ctrllimited="false"/> -->
    </default>
    <default class="ankle_pitch_vel">
      <position kv="2" ctrllimited="false"/>
      <!-- <position kv="0" ctrllimited="false"/> -->
    </default>

    <!-- Ankle Roll -->
    <default class="ankle_roll_pos">
      <position kp="300" ctrllimited="false"/>
    </default>
    <default class="ankle_roll_vel">
      <position kv="4" ctrllimited="false"/>
    </default>

    <!-- ############## -->
    <!--  Waist Gains   -->
    <!-- ############## -->
    <!-- Waist Yaw -->
    <default class="waist_yaw_pos">
      <position kp="8000" ctrllimited="false"/>
    </default>
    <default class="waist_yaw_vel">
      <position kv="10" ctrllimited="false"/>
    </default>

    <!-- Waist Roll -->
    <default class="waist_roll_pos">
      <position kp="8000" ctrllimited="false"/>
    </default>
    <default class="waist_roll_vel">
      <position kv="10" ctrllimited="false"/>
    </default>

    <!-- Waist Pitch -->
    <default class="waist_pitch_pos">
      <position kp="8000" ctrllimited="false"/>
    </default>
    <default class="waist_pitch_vel">
      <position kv="10" ctrllimited="false"/>
    </default>

    <!-- ############## -->
    <!--   Arm Gains    -->
    <!-- ############## -->
    <!-- Shoulder Pitch -->
    <default class="shoulder_pitch_pos">
      <position kp="100" ctrllimited="false"/>
    </default>
    <default class="shoulder_pitch_vel">
      <position kv="2" ctrllimited="false"/>
    </default>

    <!-- Shoulder Roll -->
    <default class="shoulder_roll_pos">
      <position kp="100" ctrllimited="false"/>
    </default>
    <default class="shoulder_roll_vel">
      <position kv="2" ctrllimited="false"/>
    </default>

    <!-- Shoulder Yaw -->
    <default class="shoulder_yaw_pos">
      <position kp="100" ctrllimited="false"/>
    </default>
    <default class="shoulder_yaw_vel">
      <position kv="2" ctrllimited="false"/>
    </default>

    <!-- Elbow -->
    <default class="elbow_pos">
      <position kp="100" ctrllimited="false"/>
    </default>
    <default class="elbow_vel">
      <position kv="2" ctrllimited="false"/>
    </default>

    <!-- Wrist Roll -->
    <default class="wrist_roll_pos">
      <position kp="300" ctrllimited="false"/>
    </default>
    <default class="wrist_roll_vel">
      <position kv="5" ctrllimited="false"/>
    </default>

    <!-- Wrist Pitch -->
    <default class="wrist_pitch_pos">
      <position kp="300" ctrllimited="false"/>
    </default>
    <default class="wrist_pitch_vel">
      <position kv="5" ctrllimited="false"/>
    </default>

    <!-- Wrist Yaw -->
    <default class="wrist_yaw_pos">
      <position kp="300" ctrllimited="false"/>
    </default>
    <default class="wrist_yaw_vel">
      <position kv="5" ctrllimited="false"/>
    </default>

    <!-- ############## -->
    <!--   Hand Gains   -->
    <!-- ############## -->
    <!-- Thumb Joint 0 -->
    <default class="thumb_joint_0_pos">
      <position kp="100" ctrllimited="false"/>
    </default>
    <default class="thumb_joint_0_vel">
      <position kv="1" ctrllimited="false"/>
    </default>

    <!-- Thumb Joint 1 -->
    <default class="thumb_joint_1_pos">
      <position kp="100" ctrllimited="false"/>
    </default>
    <default class="thumb_joint_1_vel">
      <position kv="1" ctrllimited="false"/>
    </default>

    <!-- Thumb Joint 2 -->
    <default class="thumb_joint_2_pos">
      <position kp="100" ctrllimited="false"/>
    </default>
    <default class="thumb_joint_2_vel">
      <position kv="1" ctrllimited="false"/>
    </default>

    <!-- Middle Joint 0 -->
    <default class="middle_joint_0_pos">
      <position kp="100" ctrllimited="false"/>
    </default>
    <default class="middle_joint_0_vel">
      <position kv="1" ctrllimited="false"/>
    </default>

    <!-- Middle Joint 1 -->
    <default class="middle_joint_1_pos">
      <position kp="100" ctrllimited="false"/>
    </default>
    <default class="middle_joint_1_vel">
      <position kv="1" ctrllimited="false"/>
    </default>

    <!-- Index Joint 0 -->
    <default class="index_joint_0_pos">
      <position kp="100" ctrllimited="false"/>
    </default>
    <default class="index_joint_0_vel">
      <position kv="1" ctrllimited="false"/>
    </default>

    <!-- Index Joint 1 -->
    <default class="index_joint_1_pos">
      <position kp="100" ctrllimited="false"/>
    </default>
    <default class="index_joint_1_vel">
      <position kv="1" ctrllimited="false"/>
    </default>
  </default>

  <asset>
    <mesh name="pelvis" file="pelvis.STL"/>
    <mesh name="pelvis_contour_link" file="pelvis_contour_link.STL"/>
    <mesh name="left_hip_pitch_link" file="left_hip_pitch_link.STL"/>
    <mesh name="left_hip_roll_link" file="left_hip_roll_link.STL"/>
    <mesh name="left_hip_yaw_link" file="left_hip_yaw_link.STL"/>
    <mesh name="left_knee_link" file="left_knee_link.STL"/>
    <mesh name="left_ankle_pitch_link" file="left_ankle_pitch_link.STL"/>
    <mesh name="left_ankle_roll_link" file="left_ankle_roll_link.STL"/>
    <mesh name="right_hip_pitch_link" file="right_hip_pitch_link.STL"/>
    <mesh name="right_hip_roll_link" file="right_hip_roll_link.STL"/>
    <mesh name="right_hip_yaw_link" file="right_hip_yaw_link.STL"/>
    <mesh name="right_knee_link" file="right_knee_link.STL"/>
    <mesh name="right_ankle_pitch_link" file="right_ankle_pitch_link.STL"/>
    <mesh name="right_ankle_roll_link" file="right_ankle_roll_link.STL"/>
    <mesh name="waist_yaw_link" file="waist_yaw_link.STL"/>
    <mesh name="waist_roll_link" file="waist_roll_link.STL"/>
    <mesh name="torso_link" file="torso_link.STL"/>
    <mesh name="logo_link" file="logo_link.STL"/>
    <mesh name="head_link" file="head_link.STL"/>
    <mesh name="waist_support_link" file="waist_support_link.STL"/>
    <mesh name="left_shoulder_pitch_link" file="left_shoulder_pitch_link.STL"/>
    <mesh name="left_shoulder_roll_link" file="left_shoulder_roll_link.STL"/>
    <mesh name="left_shoulder_yaw_link" file="left_shoulder_yaw_link.STL"/>
    <mesh name="left_elbow_link" file="left_elbow_link.STL"/>
    <mesh name="left_wrist_roll_link" file="left_wrist_roll_link.STL"/>
    <mesh name="left_wrist_pitch_link" file="left_wrist_pitch_link.STL"/>
    <mesh name="left_wrist_yaw_link" file="left_wrist_yaw_link.STL"/>
    <mesh name="left_hand_palm_link" file="left_hand_palm_link.STL"/>
    <mesh name="left_hand_thumb_0_link" file="left_hand_thumb_0_link.STL"/>
    <mesh name="left_hand_thumb_1_link" file="left_hand_thumb_1_link.STL"/>
    <mesh name="left_hand_thumb_2_link" file="left_hand_thumb_2_link.STL"/>
    <mesh name="left_hand_middle_0_link" file="left_hand_middle_0_link.STL"/>
    <mesh name="left_hand_middle_1_link" file="left_hand_middle_1_link.STL"/>
    <mesh name="left_hand_index_0_link" file="left_hand_index_0_link.STL"/>
    <mesh name="left_hand_index_1_link" file="left_hand_index_1_link.STL"/>
    <mesh name="right_shoulder_pitch_link" file="right_shoulder_pitch_link.STL"/>
    <mesh name="right_shoulder_roll_link" file="right_shoulder_roll_link.STL"/>
    <mesh name="right_shoulder_yaw_link" file="right_shoulder_yaw_link.STL"/>
    <mesh name="right_elbow_link" file="right_elbow_link.STL"/>
    <mesh name="right_wrist_roll_link" file="right_wrist_roll_link.STL"/>
    <mesh name="right_wrist_pitch_link" file="right_wrist_pitch_link.STL"/>
    <mesh name="right_wrist_yaw_link" file="right_wrist_yaw_link.STL"/>
    <mesh name="right_hand_palm_link" file="right_hand_palm_link.STL"/>
    <mesh name="right_hand_thumb_0_link" file="right_hand_thumb_0_link.STL"/>
    <mesh name="right_hand_thumb_1_link" file="right_hand_thumb_1_link.STL"/>
    <mesh name="right_hand_thumb_2_link" file="right_hand_thumb_2_link.STL"/>
    <mesh name="right_hand_middle_0_link" file="right_hand_middle_0_link.STL"/>
    <mesh name="right_hand_middle_1_link" file="right_hand_middle_1_link.STL"/>
    <mesh name="right_hand_index_0_link" file="right_hand_index_0_link.STL"/>
    <mesh name="right_hand_index_1_link" file="right_hand_index_1_link.STL"/>
  </asset>

  <visual>
      <headlight diffuse="0.6 0.6 0.6" ambient="0.1 0.1 0.1" specular="0.9 0.9 0.9"/>
      <rgba haze="0.15 0.25 0.35 1"/>
      <global azimuth="-140" elevation="-20"/>
  </visual>

  <asset>
      <texture type="skybox" builtin="gradient" rgb1="0.3 0.5 0.7" rgb2="0 0 0" width="512" height="3072"/>
  </asset>

  <worldbody>
    <light pos="1 0 3.5" dir="0 0 -1" directional="true"/>
    <body name="pelvis" pos="0 0 0.793">
      <inertial pos="0 0 -0.07605" quat="1 0 -0.000399148 0" mass="3.813" diaginertia="0.010549 0.0093089 0.0079184"/>
      <!-- <joint name="floating_base_joint" type="free" limited="false" actuatorfrclimited="false"/> -->
      <geom type="mesh" contype="0" conaffinity="0" group="1" density="0" rgba="0.2 0.2 0.2 1" mesh="pelvis"/>
      <geom type="mesh" contype="0" conaffinity="0" group="1" density="0" rgba="0.7 0.7 0.7 1" mesh="pelvis_contour_link"/>
      <geom type="mesh" rgba="0.7 0.7 0.7 1" mesh="pelvis_contour_link"/>
      <site name="torso_mocap_site" pos="0 0 0" euler="0 0 0"/>

      <!-- Left Leg -->
      <body name="left_hip_pitch_link" pos="0 0.064452 -0.1027">
        <inertial pos="0.002741 0.047791 -0.02606" quat="0.954862 0.293964 0.0302556 0.030122" mass="1.35" diaginertia="0.00181517 0.00153422 0.00116212"/>
        <joint name="left_hip_pitch_joint" pos="0 0 0" axis="0 1 0" range="-2.5307 2.8798" actuatorfrcrange="-88 88"/>
        <!-- <joint name="left_hip_pitch_joint" pos="0 0 0" axis="0 1 0" range="-2.5307 2.8798"/> -->
        <geom type="mesh" contype="0" conaffinity="0" group="1" density="0" rgba="0.2 0.2 0.2 1" mesh="left_hip_pitch_link"/>
        <geom type="mesh" rgba="0.2 0.2 0.2 1" mesh="left_hip_pitch_link"/>
        <body name="left_hip_roll_link" pos="0 0.052 -0.030465" quat="0.996179 0 -0.0873386 0">
          <inertial pos="0.029812 -0.001045 -0.087934" quat="0.977808 -1.97119e-05 0.205576 -0.0403793" mass="1.52" diaginertia="0.00254986 0.00241169 0.00148755"/>
          <joint name="left_hip_roll_joint" pos="0 0 0" axis="1 0 0" range="-0.5236 2.9671" actuatorfrcrange="-88 88"/>
          <!-- <joint name="left_hip_roll_joint" pos="0 0 0" axis="1 0 0" range="-0.5236 2.9671"/> -->
          <geom type="mesh" contype="0" conaffinity="0" group="1" density="0" rgba="0.7 0.7 0.7 1" mesh="left_hip_roll_link"/>
          <geom type="mesh" rgba="0.7 0.7 0.7 1" mesh="left_hip_roll_link"/>
          <body name="left_hip_yaw_link" pos="0.025001 0 -0.12412">
            <inertial pos="-0.057709 -0.010981 -0.15078" quat="0.600598 0.15832 0.223482 0.751181" mass="1.702" diaginertia="0.00776166 0.00717575 0.00160139"/>
            <joint name="left_hip_yaw_joint" pos="0 0 0" axis="0 0 1" range="-2.7576 2.7576" actuatorfrcrange="-88 88"/>
            <!-- <joint name="left_hip_yaw_joint" pos="0 0 0" axis="0 0 1" range="-2.7576 2.7576"/> -->
            <geom type="mesh" contype="0" conaffinity="0" group="1" density="0" rgba="0.7 0.7 0.7 1" mesh="left_hip_yaw_link"/>
            <geom type="mesh" rgba="0.7 0.7 0.7 1" mesh="left_hip_yaw_link"/>
            <body name="left_knee_link" pos="-0.078273 0.0021489 -0.17734" quat="0.996179 0 0.0873386 0">
              <inertial pos="0.005457 0.003964 -0.12074" quat="0.923418 -0.0327699 0.0158246 0.382067" mass="1.932" diaginertia="0.0113804 0.0112778 0.00146458"/>
              <joint name="left_knee_joint" pos="0 0 0" axis="0 1 0" range="-0.087267 2.8798" actuatorfrcrange="-139 139"/>
              <!-- <joint name="left_knee_joint" pos="0 0 0" axis="0 1 0" range="-0.087267 2.8798"/> -->
              <geom type="mesh" contype="0" conaffinity="0" group="1" density="0" rgba="0.7 0.7 0.7 1" mesh="left_knee_link"/>
              <geom type="mesh" rgba="0.7 0.7 0.7 1" mesh="left_knee_link"/>
              <body name="left_ankle_pitch_link" pos="0 -9.4445e-05 -0.30001">
                <inertial pos="-0.007269 0 0.011137" quat="0.603053 0.369225 0.369225 0.603053" mass="0.074" diaginertia="1.89e-05 1.40805e-05 6.9195e-06"/>
                <joint name="left_ankle_pitch_joint" pos="0 0 0" axis="0 1 0" range="-0.87267 0.5236" actuatorfrcrange="-50 50"/>
                <!-- <joint name="left_ankle_pitch_joint" pos="0 0 0" axis="0 1 0" range="-0.87267 0.5236"/> -->
                <geom type="mesh" contype="0" conaffinity="0" group="1" density="0" rgba="0.7 0.7 0.7 1" mesh="left_ankle_pitch_link"/>
                <geom type="mesh" rgba="0.7 0.7 0.7 1" mesh="left_ankle_pitch_link"/>
                <body name="left_ankle_roll_link" pos="0 0 -0.017558">
                  <inertial pos="0.026505 0 -0.016425" quat="-0.000481092 0.728482 -0.000618967 0.685065" mass="0.608" diaginertia="0.00167218 0.0016161 0.000217621"/>
                  <joint name="left_ankle_roll_joint" pos="0 0 0" axis="1 0 0" range="-0.2618 0.2618" actuatorfrcrange="-50 50"/>
                  <!-- <joint name="left_ankle_roll_joint" pos="0 0 0" axis="1 0 0" range="-0.2618 0.2618"/> -->
                  <geom type="mesh" contype="0" conaffinity="0" group="1" density="0" rgba="0.2 0.2 0.2 1" mesh="left_ankle_roll_link"/>
                  <geom size="0.005" pos="-0.05 0.025 -0.03" rgba="0.2 0.2 0.2 1"/>
                  <geom size="0.005" pos="-0.05 -0.025 -0.03" rgba="0.2 0.2 0.2 1"/>
                  <geom size="0.005" pos="0.12 0.03 -0.03" rgba="0.2 0.2 0.2 1"/>
                  <geom size="0.005" pos="0.12 -0.03 -0.03" rgba="0.2 0.2 0.2 1"/>
                </body>
              </body>
            </body>
          </body>
        </body>
      </body>

      <!-- Right Leg -->
      <body name="right_hip_pitch_link" pos="0 -0.064452 -0.1027">
        <inertial pos="0.002741 -0.047791 -0.02606" quat="0.954862 -0.293964 0.0302556 -0.030122" mass="1.35" diaginertia="0.00181517 0.00153422 0.00116212"/>
        <joint name="right_hip_pitch_joint" pos="0 0 0" axis="0 1 0" range="-2.5307 2.8798" actuatorfrcrange="-88 88"/>
        <!-- <joint name="right_hip_pitch_joint" pos="0 0 0" axis="0 1 0" range="-2.5307 2.8798"/> -->
        <geom type="mesh" contype="0" conaffinity="0" group="1" density="0" rgba="0.2 0.2 0.2 1" mesh="right_hip_pitch_link"/>
        <geom type="mesh" rgba="0.2 0.2 0.2 1" mesh="right_hip_pitch_link"/>
        <body name="right_hip_roll_link" pos="0 -0.052 -0.030465" quat="0.996179 0 -0.0873386 0">
          <inertial pos="0.029812 0.001045 -0.087934" quat="0.977808 1.97119e-05 0.205576 0.0403793" mass="1.52" diaginertia="0.00254986 0.00241169 0.00148755"/>
          <joint name="right_hip_roll_joint" pos="0 0 0" axis="1 0 0" range="-2.9671 0.5236" actuatorfrcrange="-88 88"/>
          <!-- <joint name="right_hip_roll_joint" pos="0 0 0" axis="1 0 0" range="-2.9671 0.5236"/> -->
          <geom type="mesh" contype="0" conaffinity="0" group="1" density="0" rgba="0.7 0.7 0.7 1" mesh="right_hip_roll_link"/>
          <geom type="mesh" rgba="0.7 0.7 0.7 1" mesh="right_hip_roll_link"/>
          <body name="right_hip_yaw_link" pos="0.025001 0 -0.12412">
            <inertial pos="-0.057709 0.010981 -0.15078" quat="0.751181 0.223482 0.15832 0.600598" mass="1.702" diaginertia="0.00776166 0.00717575 0.00160139"/>
            <joint name="right_hip_yaw_joint" pos="0 0 0" axis="0 0 1" range="-2.7576 2.7576" actuatorfrcrange="-88 88"/>
            <!-- <joint name="right_hip_yaw_joint" pos="0 0 0" axis="0 0 1" range="-2.7576 2.7576"/> -->
            <geom type="mesh" contype="0" conaffinity="0" group="1" density="0" rgba="0.7 0.7 0.7 1" mesh="right_hip_yaw_link"/>
            <geom type="mesh" rgba="0.7 0.7 0.7 1" mesh="right_hip_yaw_link"/>
            <body name="right_knee_link" pos="-0.078273 -0.0021489 -0.17734" quat="0.996179 0 0.0873386 0">
              <inertial pos="0.005457 -0.003964 -0.12074" quat="0.923439 0.0345276 0.0116333 -0.382012" mass="1.932" diaginertia="0.011374 0.0112843 0.00146452"/>
              <joint name="right_knee_joint" pos="0 0 0" axis="0 1 0" range="-0.087267 2.8798" actuatorfrcrange="-139 139"/>
              <!-- <joint name="right_knee_joint" pos="0 0 0" axis="0 1 0" range="-0.087267 2.8798"/> -->
              <geom type="mesh" contype="0" conaffinity="0" group="1" density="0" rgba="0.7 0.7 0.7 1" mesh="right_knee_link"/>
              <geom type="mesh" rgba="0.7 0.7 0.7 1" mesh="right_knee_link"/>
              <body name="right_ankle_pitch_link" pos="0 9.4445e-05 -0.30001">
                <inertial pos="-0.007269 0 0.011137" quat="0.603053 0.369225 0.369225 0.603053" mass="0.074" diaginertia="1.89e-05 1.40805e-05 6.9195e-06"/>
                <joint name="right_ankle_pitch_joint" pos="0 0 0" axis="0 1 0" range="-0.87267 0.5236" actuatorfrcrange="-50 50"/>
                <!-- <joint name="right_ankle_pitch_joint" pos="0 0 0" axis="0 1 0" range="-0.87267 0.5236"/> -->
                <geom type="mesh" contype="0" conaffinity="0" group="1" density="0" rgba="0.7 0.7 0.7 1" mesh="right_ankle_pitch_link"/>
                <geom type="mesh" rgba="0.7 0.7 0.7 1" mesh="right_ankle_pitch_link"/>
                <body name="right_ankle_roll_link" pos="0 0 -0.017558">
                  <inertial pos="0.026505 0 -0.016425" quat="0.000481092 0.728482 0.000618967 0.685065" mass="0.608" diaginertia="0.00167218 0.0016161 0.000217621"/>
                  <joint name="right_ankle_roll_joint" pos="0 0 0" axis="1 0 0" range="-0.2618 0.2618" actuatorfrcrange="-50 50"/>
                  <!-- <joint name="right_ankle_roll_joint" pos="0 0 0" axis="1 0 0" range="-0.2618 0.2618"/> -->
                  <geom type="mesh" contype="0" conaffinity="0" group="1" density="0" rgba="0.2 0.2 0.2 1" mesh="right_ankle_roll_link"/>
                  <geom size="0.005" pos="-0.05 0.025 -0.03" rgba="0.2 0.2 0.2 1"/>
                  <geom size="0.005" pos="-0.05 -0.025 -0.03" rgba="0.2 0.2 0.2 1"/>
                  <geom size="0.005" pos="0.12 0.03 -0.03" rgba="0.2 0.2 0.2 1"/>
                  <geom size="0.005" pos="0.12 -0.03 -0.03" rgba="0.2 0.2 0.2 1"/>
                </body>
              </body>
            </body>
          </body>
        </body>
      </body>
      <!-- Waist -->
      <body name="waist_yaw_link">
        <inertial pos="0.003964 0 0.018769" quat="-0.0178291 0.628464 0.0282471 0.777121" mass="0.244" diaginertia="0.000158561 0.000124229 9.67669e-05"/>
        <joint name="waist_yaw_joint" pos="0 0 0" axis="0 0 1" range="-2.618 2.618" actuatorfrcrange="-88 88"/>
        <geom type="mesh" contype="0" conaffinity="0" group="1" density="0" rgba="0.7 0.7 0.7 1" mesh="waist_yaw_link"/>
        <body name="waist_roll_link" pos="-0.0039635 0 0.035">
          <inertial pos="0 -0.000236 0.010111" quat="0.99979 0.020492 0 0" mass="0.047" diaginertia="7.515e-06 6.40206e-06 3.98394e-06"/>
          <joint name="waist_roll_joint" pos="0 0 0" axis="1 0 0" range="-0.52 0.52" actuatorfrcrange="-50 50"/>
          <geom type="mesh" contype="0" conaffinity="0" group="1" density="0" rgba="0.7 0.7 0.7 1" mesh="waist_roll_link"/>
          <body name="torso_link" pos="0 0 0.019">
            <inertial pos="0.00331658 0.000261533 0.179856" quat="0.999831 0.000376204 0.0179895 -0.00377704" mass="9.598" diaginertia="0.12407 0.111951 0.0325382"/>
            <joint name="waist_pitch_joint" pos="0 0 0" axis="0 1 0" range="-0.52 0.52" actuatorfrcrange="-50 50"/>
            <geom type="mesh" contype="0" conaffinity="0" group="1" density="0" rgba="0.7 0.7 0.7 1" mesh="torso_link"/>
            <geom type="mesh" rgba="0.7 0.7 0.7 1" mesh="torso_link"/>
            <geom pos="0.0039635 0 -0.054" quat="1 0 0 0" type="mesh" contype="0" conaffinity="0" group="1" density="0" rgba="0.2 0.2 0.2 1" mesh="logo_link"/>
            <geom pos="0.0039635 0 -0.054" quat="1 0 0 0" type="mesh" rgba="0.2 0.2 0.2 1" mesh="logo_link"/>
            <geom pos="0.0039635 0 -0.054" type="mesh" contype="0" conaffinity="0" group="1" density="0" rgba="0.2 0.2 0.2 1" mesh="head_link"/>
            <geom pos="0.0039635 0 -0.054" type="mesh" rgba="0.2 0.2 0.2 1" mesh="head_link"/>
            <geom pos="0.0039635 0 -0.054" quat="1 0 0 0" type="mesh" contype="0" conaffinity="0" group="1" density="0" rgba="0.7 0.7 0.7 1" mesh="waist_support_link"/>
            <geom pos="0.0039635 0 -0.054" quat="1 0 0 0" type="mesh" rgba="0.7 0.7 0.7 1" mesh="waist_support_link"/>
            <site name="imu" size="0.01" pos="-0.03959 -0.00224 0.13792"/>

            <!-- Left Arm -->
            <body name="left_shoulder_pitch_link" pos="0.0039563 0.10022 0.23778" quat="0.990264 0.139201 1.38722e-05 -9.86868e-05">
              <inertial pos="0 0.035892 -0.011628" quat="0.654152 0.0130458 -0.326267 0.68225" mass="0.718" diaginertia="0.000465864 0.000432842 0.000406394"/>
              <joint name="left_shoulder_pitch_joint" pos="0 0 0" axis="0 1 0" range="-3.0892 2.6704" actuatorfrcrange="-25 25"/>
              <geom type="mesh" contype="0" conaffinity="0" group="1" density="0" rgba="0.7 0.7 0.7 1" mesh="left_shoulder_pitch_link"/>
              <geom size="0.03 0.025" pos="0 0.04 -0.01" quat="0.707107 0 0.707107 0" type="cylinder" rgba="0.7 0.7 0.7 1"/>
              <body name="left_shoulder_roll_link" pos="0 0.038 -0.013831" quat="0.990268 -0.139172 0 0">
                <inertial pos="-0.000227 0.00727 -0.063243" quat="0.701256 -0.0196223 -0.00710317 0.712604" mass="0.643" diaginertia="0.000691311 0.000618011 0.000388977"/>
                <joint name="left_shoulder_roll_joint" pos="0 0 0" axis="1 0 0" range="-1.5882 2.2515" actuatorfrcrange="-25 25"/>
                <geom type="mesh" contype="0" conaffinity="0" group="1" density="0" rgba="0.7 0.7 0.7 1" mesh="left_shoulder_roll_link"/>
                <geom size="0.03 0.015" pos="-0.004 0.006 -0.053" type="cylinder" rgba="0.7 0.7 0.7 1"/>
                <body name="left_shoulder_yaw_link" pos="0 0.00624 -0.1032">
                  <inertial pos="0.010773 -0.002949 -0.072009" quat="0.716879 -0.0964829 -0.0679942 0.687134" mass="0.734" diaginertia="0.00106187 0.00103217 0.000400661"/>
                  <joint name="left_shoulder_yaw_joint" pos="0 0 0" axis="0 0 1" range="-2.618 2.618" actuatorfrcrange="-25 25"/>
                  <geom type="mesh" contype="0" conaffinity="0" group="1" density="0" rgba="0.7 0.7 0.7 1" mesh="left_shoulder_yaw_link"/>
                  <geom type="mesh" rgba="0.7 0.7 0.7 1" mesh="left_shoulder_yaw_link"/>
                  <body name="left_elbow_link" pos="0.015783 0 -0.080518">
                    <inertial pos="0.064956 0.004454 -0.010062" quat="0.541765 0.636132 0.388821 0.388129" mass="0.6" diaginertia="0.000443035 0.000421612 0.000259353"/>
                    <joint name="left_elbow_joint" pos="0 0 0" axis="0 1 0" range="-1.0472 2.0944" actuatorfrcrange="-25 25"/>
                    <geom type="mesh" contype="0" conaffinity="0" group="1" density="0" rgba="0.7 0.7 0.7 1" mesh="left_elbow_link"/>
                    <geom type="mesh" rgba="0.7 0.7 0.7 1" mesh="left_elbow_link"/>
                    <body name="left_wrist_roll_link" pos="0.1 0.00188791 -0.01">
                      <inertial pos="0.0171394 0.000537591 4.8864e-07" quat="0.575338 0.411667 -0.574906 0.411094" mass="0.085445" diaginertia="5.48211e-05 4.96646e-05 3.57798e-05"/>
                      <joint name="left_wrist_roll_joint" pos="0 0 0" axis="1 0 0" range="-1.97222 1.97222" actuatorfrcrange="-25 25"/>
                      <geom type="mesh" contype="0" conaffinity="0" group="1" density="0" rgba="0.7 0.7 0.7 1" mesh="left_wrist_roll_link"/>
                      <geom type="mesh" rgba="0.7 0.7 0.7 1" mesh="left_wrist_roll_link"/>
                      <body name="left_wrist_pitch_link" pos="0.038 0 0">
                        <inertial pos="0.0229999 -0.00111685 -0.00111658" quat="0.249998 0.661363 0.293036 0.643608" mass="0.48405" diaginertia="0.000430353 0.000429873 0.000164648"/>
                        <joint name="left_wrist_pitch_joint" pos="0 0 0" axis="0 1 0" range="-1.61443 1.61443" actuatorfrcrange="-5 5"/>
                        <geom type="mesh" contype="0" conaffinity="0" group="1" density="0" rgba="0.7 0.7 0.7 1" mesh="left_wrist_pitch_link"/>
                        <geom type="mesh" rgba="0.7 0.7 0.7 1" mesh="left_wrist_pitch_link"/>
                        <body name="left_wrist_yaw_link" pos="0.046 0 0">
                          <inertial pos="0.0885506 0.00212216 -0.000374562" quat="0.487149 0.493844 0.513241 0.505358" mass="0.457415" diaginertia="0.00105989 0.000895419 0.000323842"/>
                          <joint name="left_wrist_yaw_joint" pos="0 0 0" axis="0 0 1" range="-1.61443 1.61443" actuatorfrcrange="-5 5"/>
                          <geom type="mesh" contype="0" conaffinity="0" group="1" density="0" rgba="0.7 0.7 0.7 1" mesh="left_wrist_yaw_link"/>
                          <geom type="mesh" rgba="0.7 0.7 0.7 1" mesh="left_wrist_yaw_link"/>
                          <geom pos="0.0415 0.003 0" quat="1 0 0 0" type="mesh" contype="0" conaffinity="0" group="1" density="0" rgba="0.7 0.7 0.7 1" mesh="left_hand_palm_link"/>
                          <geom pos="0.0415 0.003 0" quat="1 0 0 0" type="mesh" rgba="0.7 0.7 0.7 1" mesh="left_hand_palm_link"/>

                          <!-- Left Hand -->
                          <body name="left_hand_thumb_0_link" pos="0.067 0.003 0">
                            <inertial pos="-0.000884246 -0.00863407 0.000944293" quat="0.462991 0.643965 -0.460173 0.398986" mass="0.0862366" diaginertia="1.6546e-05 1.60058e-05 1.43741e-05"/>
                            <joint name="left_hand_thumb_0_joint" pos="0 0 0" axis="0 1 0" range="-1.0472 1.0472" actuatorfrcrange="-2.45 2.45"/>
                            <geom type="mesh" contype="0" conaffinity="0" group="1" density="0" rgba="0.7 0.7 0.7 1" mesh="left_hand_thumb_0_link"/>
                            <geom type="mesh" rgba="0.7 0.7 0.7 1" mesh="left_hand_thumb_0_link"/>
                            <body name="left_hand_thumb_1_link" pos="-0.0025 -0.0193 0">
                              <inertial pos="-0.000827888 -0.0354744 -0.0003809" quat="0.685598 0.705471 -0.15207 0.0956069" mass="0.0588507" diaginertia="1.28514e-05 1.22902e-05 5.9666e-06"/>
                              <joint name="left_hand_thumb_1_joint" pos="0 0 0" axis="0 0 1" range="-0.724312 1.0472" actuatorfrcrange="-1.4 1.4"/>
                              <geom type="mesh" contype="0" conaffinity="0" group="1" density="0" rgba="0.7 0.7 0.7 1" mesh="left_hand_thumb_1_link"/>
                              <geom size="0.01 0.015 0.01" pos="-0.001 -0.032 0" type="box" rgba="0.7 0.7 0.7 1"/>
                              <body name="left_hand_thumb_2_link" pos="0 -0.0458 0">
                                <inertial pos="-0.00171735 -0.0262819 0.000107789" quat="0.703174 0.710977 -0.00017564 -0.00766553" mass="0.0203063" diaginertia="4.61314e-06 3.86645e-06 1.53495e-06"/>
                                <joint name="left_hand_thumb_2_joint" pos="0 0 0" axis="0 0 1" range="0 1.74533" actuatorfrcrange="-1.4 1.4"/>
                                <geom type="mesh" contype="0" conaffinity="0" group="1" density="0" rgba="0.7 0.7 0.7 1" mesh="left_hand_thumb_2_link"/>
                                <geom type="mesh" rgba="0.7 0.7 0.7 1" mesh="left_hand_thumb_2_link"/>
                              </body>
                            </body>
                          </body>
                          <body name="left_hand_middle_0_link" pos="0.1192 0.0046 -0.0285">
                            <inertial pos="0.0354744 0.000827888 0.0003809" quat="0.391313 0.552395 0.417187 0.606373" mass="0.0588507" diaginertia="1.28514e-05 1.22902e-05 5.9666e-06"/>
                            <joint name="left_hand_middle_0_joint" pos="0 0 0" axis="0 0 1" range="-1.5708 0" actuatorfrcrange="-1.4 1.4"/>
                            <geom type="mesh" contype="0" conaffinity="0" group="1" density="0" rgba="0.7 0.7 0.7 1" mesh="left_hand_middle_0_link"/>
                            <geom type="mesh" rgba="0.7 0.7 0.7 1" mesh="left_hand_middle_0_link"/>
                            <body name="left_hand_middle_1_link" pos="0.0458 0 0">
                              <inertial pos="0.0262819 0.00171735 -0.000107789" quat="0.502612 0.491799 0.502639 0.502861" mass="0.0203063" diaginertia="4.61314e-06 3.86645e-06 1.53495e-06"/>
                              <joint name="left_hand_middle_1_joint" pos="0 0 0" axis="0 0 1" range="-1.74533 0" actuatorfrcrange="-1.4 1.4"/>
                              <geom type="mesh" contype="0" conaffinity="0" group="1" density="0" rgba="0.7 0.7 0.7 1" mesh="left_hand_middle_1_link"/>
                              <geom type="mesh" rgba="0.7 0.7 0.7 1" mesh="left_hand_middle_1_link"/>
                            </body>
                          </body>
                          <body name="left_hand_index_0_link" pos="0.1192 0.0046 0.0285">
                            <inertial pos="0.0354744 0.000827888 0.0003809" quat="0.391313 0.552395 0.417187 0.606373" mass="0.0588507" diaginertia="1.28514e-05 1.22902e-05 5.9666e-06"/>
                            <joint name="left_hand_index_0_joint" pos="0 0 0" axis="0 0 1" range="-1.5708 0" actuatorfrcrange="-1.4 1.4"/>
                            <geom type="mesh" contype="0" conaffinity="0" group="1" density="0" rgba="0.7 0.7 0.7 1" mesh="left_hand_index_0_link"/>
                            <geom type="mesh" rgba="0.7 0.7 0.7 1" mesh="left_hand_index_0_link"/>
                            <body name="left_hand_index_1_link" pos="0.0458 0 0">
                              <inertial pos="0.0262819 0.00171735 -0.000107789" quat="0.502612 0.491799 0.502639 0.502861" mass="0.0203063" diaginertia="4.61314e-06 3.86645e-06 1.53495e-06"/>
                              <joint name="left_hand_index_1_joint" pos="0 0 0" axis="0 0 1" range="-1.74533 0" actuatorfrcrange="-1.4 1.4"/>
                              <geom type="mesh" contype="0" conaffinity="0" group="1" density="0" rgba="0.7 0.7 0.7 1" mesh="left_hand_index_1_link"/>
                              <geom type="mesh" rgba="0.7 0.7 0.7 1" mesh="left_hand_index_1_link"/>
                            </body>
                          </body>
                        </body>
                      </body>
                    </body>
                  </body>
                </body>
              </body>
            </body>

            <!-- Right Arm -->
            <body name="right_shoulder_pitch_link" pos="0.0039563 -0.10021 0.23778" quat="0.990264 -0.139201 1.38722e-05 9.86868e-05">
              <inertial pos="0 -0.035892 -0.011628" quat="0.68225 -0.326267 0.0130458 0.654152" mass="0.718" diaginertia="0.000465864 0.000432842 0.000406394"/>
              <joint name="right_shoulder_pitch_joint" pos="0 0 0" axis="0 1 0" range="-3.0892 2.6704" actuatorfrcrange="-25 25"/>
              <geom type="mesh" contype="0" conaffinity="0" group="1" density="0" rgba="0.7 0.7 0.7 1" mesh="right_shoulder_pitch_link"/>
              <geom size="0.03 0.025" pos="0 -0.04 -0.01" quat="0.707107 0 0.707107 0" type="cylinder" rgba="0.7 0.7 0.7 1"/>
              <body name="right_shoulder_roll_link" pos="0 -0.038 -0.013831" quat="0.990268 0.139172 0 0">
                <inertial pos="-0.000227 -0.00727 -0.063243" quat="0.712604 -0.00710317 -0.0196223 0.701256" mass="0.643" diaginertia="0.000691311 0.000618011 0.000388977"/>
                <joint name="right_shoulder_roll_joint" pos="0 0 0" axis="1 0 0" range="-2.2515 1.5882" actuatorfrcrange="-25 25"/>
                <geom type="mesh" contype="0" conaffinity="0" group="1" density="0" rgba="0.7 0.7 0.7 1" mesh="right_shoulder_roll_link"/>
                <geom size="0.03 0.015" pos="-0.004 -0.006 -0.053" type="cylinder" rgba="0.7 0.7 0.7 1"/>
                <body name="right_shoulder_yaw_link" pos="0 -0.00624 -0.1032">
                  <inertial pos="0.010773 0.002949 -0.072009" quat="0.687134 -0.0679942 -0.0964829 0.716879" mass="0.734" diaginertia="0.00106187 0.00103217 0.000400661"/>
                  <joint name="right_shoulder_yaw_joint" pos="0 0 0" axis="0 0 1" range="-2.618 2.618" actuatorfrcrange="-25 25"/>
                  <geom type="mesh" contype="0" conaffinity="0" group="1" density="0" rgba="0.7 0.7 0.7 1" mesh="right_shoulder_yaw_link"/>
                  <geom type="mesh" rgba="0.7 0.7 0.7 1" mesh="right_shoulder_yaw_link"/>
                  <body name="right_elbow_link" pos="0.015783 0 -0.080518">
                    <inertial pos="0.064956 -0.004454 -0.010062" quat="0.388129 0.388821 0.636132 0.541765" mass="0.6" diaginertia="0.000443035 0.000421612 0.000259353"/>
                    <joint name="right_elbow_joint" pos="0 0 0" axis="0 1 0" range="-1.0472 2.0944" actuatorfrcrange="-25 25"/>
                    <geom type="mesh" contype="0" conaffinity="0" group="1" density="0" rgba="0.7 0.7 0.7 1" mesh="right_elbow_link"/>
                    <geom type="mesh" rgba="0.7 0.7 0.7 1" mesh="right_elbow_link"/>
                    <body name="right_wrist_roll_link" pos="0.1 -0.00188791 -0.01">
                      <inertial pos="0.0171394 -0.000537591 4.8864e-07" quat="0.411667 0.575338 -0.411094 0.574906" mass="0.085445" diaginertia="5.48211e-05 4.96646e-05 3.57798e-05"/>
                      <joint name="right_wrist_roll_joint" pos="0 0 0" axis="1 0 0" range="-1.97222 1.97222" actuatorfrcrange="-25 25"/>
                      <geom type="mesh" contype="0" conaffinity="0" group="1" density="0" rgba="0.7 0.7 0.7 1" mesh="right_wrist_roll_link"/>
                      <geom type="mesh" rgba="0.7 0.7 0.7 1" mesh="right_wrist_roll_link"/>
                      <body name="right_wrist_pitch_link" pos="0.038 0 0">
                        <inertial pos="0.0229999 0.00111685 -0.00111658" quat="0.643608 0.293036 0.661363 0.249998" mass="0.48405" diaginertia="0.000430353 0.000429873 0.000164648"/>
                        <joint name="right_wrist_pitch_joint" pos="0 0 0" axis="0 1 0" range="-1.61443 1.61443" actuatorfrcrange="-5 5"/>
                        <geom type="mesh" contype="0" conaffinity="0" group="1" density="0" rgba="0.7 0.7 0.7 1" mesh="right_wrist_pitch_link"/>
                        <geom type="mesh" rgba="0.7 0.7 0.7 1" mesh="right_wrist_pitch_link"/>
                        <body name="right_wrist_yaw_link" pos="0.046 0 0">
                          <inertial pos="0.0885506 -0.00212216 -0.000374562" quat="0.505358 0.513241 0.493844 0.487149" mass="0.457415" diaginertia="0.00105989 0.000895419 0.000323842"/>
                          <joint name="right_wrist_yaw_joint" pos="0 0 0" axis="0 0 1" range="-1.61443 1.61443" actuatorfrcrange="-5 5"/>
                          <geom type="mesh" contype="0" conaffinity="0" group="1" density="0" rgba="0.7 0.7 0.7 1" mesh="right_wrist_yaw_link"/>
                          <geom type="mesh" rgba="0.7 0.7 0.7 1" mesh="right_wrist_yaw_link"/>
                          <geom pos="0.0415 -0.003 0" quat="1 0 0 0" type="mesh" contype="0" conaffinity="0" group="1" density="0" rgba="0.7 0.7 0.7 1" mesh="right_hand_palm_link"/>
                          <geom pos="0.0415 -0.003 0" quat="1 0 0 0" type="mesh" rgba="0.7 0.7 0.7 1" mesh="right_hand_palm_link"/>

                          <!-- Right Hand -->
                          <body name="right_hand_thumb_0_link" pos="0.067 -0.003 0">
                            <inertial pos="-0.000884246 0.00863407 0.000944293" quat="0.643965 0.462991 -0.398986 0.460173" mass="0.0862366" diaginertia="1.6546e-05 1.60058e-05 1.43741e-05"/>
                            <joint name="right_hand_thumb_0_joint" pos="0 0 0" axis="0 1 0" range="-1.0472 1.0472" actuatorfrcrange="-2.45 2.45"/>
                            <geom type="mesh" contype="0" conaffinity="0" group="1" density="0" rgba="0.7 0.7 0.7 1" mesh="right_hand_thumb_0_link"/>
                            <geom type="mesh" rgba="0.7 0.7 0.7 1" mesh="right_hand_thumb_0_link"/>
                            <body name="right_hand_thumb_1_link" pos="-0.0025 0.0193 0">
                              <inertial pos="-0.000827888 0.0354744 -0.0003809" quat="0.705471 0.685598 -0.0956069 0.15207" mass="0.0588507" diaginertia="1.28514e-05 1.22902e-05 5.9666e-06"/>
                              <joint name="right_hand_thumb_1_joint" pos="0 0 0" axis="0 0 1" range="-1.0472 0.724312" actuatorfrcrange="-1.4 1.4"/>
                              <geom type="mesh" contype="0" conaffinity="0" group="1" density="0" rgba="0.7 0.7 0.7 1" mesh="right_hand_thumb_1_link"/>
                              <geom size="0.01 0.015 0.01" pos="-0.001 0.032 0" type="box" rgba="0.7 0.7 0.7 1"/>
                              <body name="right_hand_thumb_2_link" pos="0 0.0458 0">
                                <inertial pos="-0.00171735 0.0262819 0.000107789" quat="0.710977 0.703174 0.00766553 0.00017564" mass="0.0203063" diaginertia="4.61314e-06 3.86645e-06 1.53495e-06"/>
                                <joint name="right_hand_thumb_2_joint" pos="0 0 0" axis="0 0 1" range="-1.74533 0" actuatorfrcrange="-1.4 1.4"/>
                                <geom type="mesh" contype="0" conaffinity="0" group="1" density="0" rgba="0.7 0.7 0.7 1" mesh="right_hand_thumb_2_link"/>
                                <geom type="mesh" rgba="0.7 0.7 0.7 1" mesh="right_hand_thumb_2_link"/>
                              </body>
                            </body>
                          </body>
                          <body name="right_hand_middle_0_link" pos="0.1192 -0.0046 -0.0285">
                            <inertial pos="0.0354744 -0.000827888 0.0003809" quat="0.606373 0.417187 0.552395 0.391313" mass="0.0588507" diaginertia="1.28514e-05 1.22902e-05 5.9666e-06"/>
                            <joint name="right_hand_middle_0_joint" pos="0 0 0" axis="0 0 1" range="0 1.5708" actuatorfrcrange="-1.4 1.4"/>
                            <geom type="mesh" contype="0" conaffinity="0" group="1" density="0" rgba="0.7 0.7 0.7 1" mesh="right_hand_middle_0_link"/>
                            <geom type="mesh" rgba="0.7 0.7 0.7 1" mesh="right_hand_middle_0_link"/>
                            <body name="right_hand_middle_1_link" pos="0.0458 0 0">
                              <inertial pos="0.0262819 -0.00171735 -0.000107789" quat="0.502861 0.502639 0.491799 0.502612" mass="0.0203063" diaginertia="4.61314e-06 3.86645e-06 1.53495e-06"/>
                              <joint name="right_hand_middle_1_joint" pos="0 0 0" axis="0 0 1" range="0 1.74533" actuatorfrcrange="-1.4 1.4"/>
                              <geom type="mesh" contype="0" conaffinity="0" group="1" density="0" rgba="0.7 0.7 0.7 1" mesh="right_hand_middle_1_link"/>
                              <geom type="mesh" rgba="0.7 0.7 0.7 1" mesh="right_hand_middle_1_link"/>
                            </body>
                          </body>
                          <body name="right_hand_index_0_link" pos="0.1192 -0.0046 0.0285">
                            <inertial pos="0.0354744 -0.000827888 0.0003809" quat="0.606373 0.417187 0.552395 0.391313" mass="0.0588507" diaginertia="1.28514e-05 1.22902e-05 5.9666e-06"/>
                            <joint name="right_hand_index_0_joint" pos="0 0 0" axis="0 0 1" range="0 1.5708" actuatorfrcrange="-1.4 1.4"/>
                            <geom type="mesh" contype="0" conaffinity="0" group="1" density="0" rgba="0.7 0.7 0.7 1" mesh="right_hand_index_0_link"/>
                            <geom type="mesh" rgba="0.7 0.7 0.7 1" mesh="right_hand_index_0_link"/>
                            <body name="right_hand_index_1_link" pos="0.0458 0 0">
                              <inertial pos="0.0262819 -0.00171735 -0.000107789" quat="0.502861 0.502639 0.491799 0.502612" mass="0.0203063" diaginertia="4.61314e-06 3.86645e-06 1.53495e-06"/>
                              <joint name="right_hand_index_1_joint" pos="0 0 0" axis="0 0 1" range="0 1.74533" actuatorfrcrange="-1.4 1.4"/>
                              <geom type="mesh" contype="0" conaffinity="0" group="1" density="0" rgba="0.7 0.7 0.7 1" mesh="right_hand_index_1_link"/>
                              <geom type="mesh" rgba="0.7 0.7 0.7 1" mesh="right_hand_index_1_link"/>
                            </body>
                          </body>
                        </body>
                      </body>
                    </body>
                  </body>
                </body>
              </body>
            </body>
          </body>
        </body>
      </body>
    </body>
  </worldbody>

  <actuator>
    <!-- ################## -->
    <!-- Position Actuation -->
    <!-- ################## -->
    <!-- Left Leg -->
    <position name="left_hip_pitch_joint_pos" class="hip_pitch_pos" joint="left_hip_pitch_joint"/>
    <position name="left_hip_roll_joint_pos" class="hip_roll_pos" joint="left_hip_roll_joint"/>
    <position name="left_hip_yaw_joint_pos" class="hip_yaw_pos" joint="left_hip_yaw_joint"/>
    <position name="left_knee_joint_pos" class="knee_pos" joint="left_knee_joint"/>
    <position name="left_ankle_pitch_joint_pos" class="ankle_pitch_pos" joint="left_ankle_pitch_joint"/>
    <position name="left_ankle_roll_joint_pos" class="ankle_roll_pos" joint="left_ankle_roll_joint"/>

    <!-- Right Leg -->
    <position name="right_hip_pitch_joint_pos" class="hip_pitch_pos" joint="right_hip_pitch_joint"/>
    <position name="right_hip_roll_joint_pos" class="hip_roll_pos" joint="right_hip_roll_joint"/>
    <position name="right_hip_yaw_joint_pos" class="hip_yaw_pos" joint="right_hip_yaw_joint"/>
    <position name="right_knee_joint_pos" class="knee_pos" joint="right_knee_joint"/>
    <position name="right_ankle_pitch_joint_pos" class="ankle_pitch_pos" joint="right_ankle_pitch_joint"/>
    <position name="right_ankle_roll_joint_pos" class="ankle_roll_pos" joint="right_ankle_roll_joint"/>

    <!-- Waist -->
    <position name="waist_yaw_joint_pos" class="waist_yaw_pos" joint="waist_yaw_joint"/>
    <position name="waist_roll_joint_pos" class="waist_roll_pos" joint="waist_roll_joint"/>
    <position name="waist_pitch_joint_pos" class="waist_pitch_pos" joint="waist_pitch_joint"/>

    <!-- Left Arm -->
    <position name="left_shoulder_pitch_joint_pos" class="shoulder_pitch_pos" joint="left_shoulder_pitch_joint"/>
    <position name="left_shoulder_roll_joint_pos" class="shoulder_roll_pos" joint="left_shoulder_roll_joint"/>
    <position name="left_shoulder_yaw_joint_pos" class="shoulder_yaw_pos" joint="left_shoulder_yaw_joint"/>
    <position name="left_elbow_joint_pos" class="elbow_pos" joint="left_elbow_joint"/>
    <position name="left_wrist_roll_joint_pos" class="wrist_roll_pos" joint="left_wrist_roll_joint"/>
    <position name="left_wrist_pitch_joint_pos" class="wrist_pitch_pos" joint="left_wrist_pitch_joint"/>
    <position name="left_wrist_yaw_joint_pos" class="wrist_yaw_pos" joint="left_wrist_yaw_joint"/>

    <!-- Left Hand -->
    <!-- <position name="left_hand_thumb_0_joint_pos" class="thumb_joint_0_pos" joint="left_hand_thumb_0_joint"/>
    <position name="left_hand_thumb_1_joint_pos" class="thumb_joint_1_pos" joint="left_hand_thumb_1_joint"/>
    <position name="left_hand_thumb_2_joint_pos" class="thumb_joint_2_pos" joint="left_hand_thumb_2_joint"/>
    <position name="left_hand_middle_0_joint_pos" class="middle_joint_0_pos" joint="left_hand_middle_0_joint"/>
    <position name="left_hand_middle_1_joint_pos" class="middle_joint_1_pos" joint="left_hand_middle_1_joint"/>
    <position name="left_hand_index_0_joint_pos" class="index_joint_0_pos" joint="left_hand_index_0_joint"/>
    <position name="left_hand_index_1_joint_pos" class="index_joint_1_pos" joint="left_hand_index_1_joint"/> -->

    <!-- Right Arm -->
    <position name="right_shoulder_pitch_joint_pos" class="shoulder_pitch_pos" joint="right_shoulder_pitch_joint"/>
    <position name="right_shoulder_roll_join_post" class="shoulder_roll_pos" joint="right_shoulder_roll_joint"/>
    <position name="right_shoulder_yaw_joint_pos" class="shoulder_yaw_pos" joint="right_shoulder_yaw_joint"/>
    <position name="right_elbow_joint_pos" class="elbow_pos" joint="right_elbow_joint"/>
    <position name="right_wrist_roll_joint_pos" class="wrist_roll_pos" joint="right_wrist_roll_joint"/>
    <position name="right_wrist_pitch_joint_pos" class="wrist_pitch_pos" joint="right_wrist_pitch_joint"/>
    <position name="right_wrist_yaw_joint_pos" class="wrist_yaw_pos"joint="right_wrist_yaw_joint"/>

    <!-- Right Hand -->
    <!-- <position name="right_hand_thumb_0_joint_pos" class="thumb_joint_0_pos" joint="right_hand_thumb_0_joint"/>
    <position name="right_hand_thumb_1_joint_pos" class="thumb_joint_1_pos" joint="right_hand_thumb_1_joint"/>
    <position name="right_hand_thumb_2_joint_pos" class="thumb_joint_2_pos" joint="right_hand_thumb_2_joint"/>
    <position name="right_hand_index_0_joint_pos" class="middle_joint_0_pos" joint="right_hand_index_0_joint"/>
    <position name="right_hand_index_1_joint_pos" class="middle_joint_1_pos" joint="right_hand_index_1_joint"/>
    <position name="right_hand_middle_0_joint_pos" class="index_joint_0_pos" joint="right_hand_middle_0_joint"/>
    <position name="right_hand_middle_1_joint_pos" class="index_joint_1_pos" joint="right_hand_middle_1_joint"/> -->

    <!-- ################## -->
    <!-- Velocity Actuation -->
    <!-- ################## -->
    <!-- Left Leg -->
    <velocity name="left_hip_pitch_joint_vel" class="hip_pitch_vel" joint="left_hip_pitch_joint"/>
    <velocity name="left_hip_roll_joint_vel" class="hip_roll_vel" joint="left_hip_roll_joint"/>
    <velocity name="left_hip_yaw_joint_vel" class="hip_yaw_vel" joint="left_hip_yaw_joint"/>
    <velocity name="left_knee_joint_vel" class="knee_vel" joint="left_knee_joint"/>
    <velocity name="left_ankle_pitch_joint_vel" class="ankle_pitch_vel" joint="left_ankle_pitch_joint"/>
    <velocity name="left_ankle_roll_joint_vel" class="ankle_roll_vel" joint="left_ankle_roll_joint"/>

    <!-- Right Leg -->
    <velocity name="right_hip_pitch_joint_vel" class="hip_pitch_vel" joint="right_hip_pitch_joint"/>
    <velocity name="right_hip_roll_joint_vel" class="hip_roll_vel" joint="right_hip_roll_joint"/>
    <velocity name="right_hip_yaw_joint_vel" class="hip_yaw_vel" joint="right_hip_yaw_joint"/>
    <velocity name="right_knee_joint_vel" class="knee_vel" joint="right_knee_joint"/>
    <velocity name="right_ankle_pitch_joint_vel" class="ankle_pitch_vel" joint="right_ankle_pitch_joint"/>
    <velocity name="right_ankle_roll_joint_vel" class="ankle_roll_vel" joint="right_ankle_roll_joint"/>

    <!-- Waist -->
    <velocity name="waist_yaw_joint_vel" class="waist_yaw_vel" joint="waist_yaw_joint"/>
    <velocity name="waist_roll_joint_vel" class="waist_roll_vel" joint="waist_roll_joint"/>
    <velocity name="waist_pitch_joint_vel" class="waist_pitch_vel" joint="waist_pitch_joint"/>

    <!-- Left Arm -->
    <velocity name="left_shoulder_pitch_joint_vel" class="shoulder_pitch_vel" joint="left_shoulder_pitch_joint"/>
    <velocity name="left_shoulder_roll_joint_vel" class="shoulder_roll_vel" joint="left_shoulder_roll_joint"/>
    <velocity name="left_shoulder_yaw_joint_vel" class="shoulder_yaw_vel" joint="left_shoulder_yaw_joint"/>
    <velocity name="left_elbow_joint_vel" class="elbow_vel" joint="left_elbow_joint"/>
    <velocity name="left_wrist_roll_joint_vel" class="wrist_roll_vel" joint="left_wrist_roll_joint"/>
    <velocity name="left_wrist_pitch_joint_vel" class="wrist_pitch_vel" joint="left_wrist_pitch_joint"/>
    <velocity name="left_wrist_yaw_joint_vel" class="wrist_yaw_vel" joint="left_wrist_yaw_joint"/>

    <!-- Left Hand -->
    <!-- <velocity name="left_hand_thumb_0_joint_vel" class="thumb_joint_0_pos" joint="left_hand_thumb_0_joint"/>
    <velocity name="left_hand_thumb_1_joint_vel" class="thumb_joint_1_pos" joint="left_hand_thumb_1_joint"/>
    <velocity name="left_hand_thumb_2_joint_vel" class="thumb_joint_2_pos" joint="left_hand_thumb_2_joint"/>
    <velocity name="left_hand_middle_0_joint_vel" class="middle_joint_0_pos" joint="left_hand_middle_0_joint"/>
    <velocity name="left_hand_middle_1_joint_vel" class="middle_joint_1_pos" joint="left_hand_middle_1_joint"/>
    <velocity name="left_hand_index_0_joint_vel" class="index_joint_0_pos" joint="left_hand_index_0_joint"/>
    <velocity name="left_hand_index_1_joint_vel" class="index_joint_1_pos" joint="left_hand_index_1_joint"/> -->

    <!-- Right Arm -->
    <velocity name="right_shoulder_pitch_joint_vel" class="shoulder_pitch_vel" joint="right_shoulder_pitch_joint"/>
    <velocity name="right_shoulder_roll_joint_vel" class="shoulder_roll_vel" joint="right_shoulder_roll_joint"/>
    <velocity name="right_shoulder_yaw_joint_vel" class="shoulder_yaw_vel" joint="right_shoulder_yaw_joint"/>
    <velocity name="right_elbow_joint_vel" class="elbow_vel" joint="right_elbow_joint"/>
    <velocity name="right_wrist_roll_joint_vel" class="wrist_roll_vel" joint="right_wrist_roll_joint"/>
    <velocity name="right_wrist_pitch_joint_vel" class="wrist_pitch_vel" joint="right_wrist_pitch_joint"/>
    <velocity name="right_wrist_yaw_joint_vel" class="wrist_yaw_vel" joint="right_wrist_yaw_joint"/>

    <!-- Right Hand -->
    <!-- <velocity name="right_hand_thumb_0_joint_vel" class="thumb_joint_0_pos" joint="right_hand_thumb_0_joint"/>
    <velocity name="right_hand_thumb_1_joint_vel" class="thumb_joint_1_pos" joint="right_hand_thumb_1_joint"/>
    <velocity name="right_hand_thumb_2_joint_vel" class="thumb_joint_2_pos" joint="right_hand_thumb_2_joint"/>
    <velocity name="right_hand_index_0_joint_vel" class="middle_joint_0_pos" joint="right_hand_index_0_joint"/>
    <velocity name="right_hand_index_1_joint_vel" class="middle_joint_1_pos" joint="right_hand_index_1_joint"/>
    <velocity name="right_hand_middle_0_joint_vel" class="index_joint_0_pos" joint="right_hand_middle_0_joint"/>
    <velocity name="right_hand_middle_1_joint_vel" class="index_joint_1_pos" joint="right_hand_middle_1_joint"/> -->

    <!-- ################ -->
    <!-- Torque Actuation -->
    <!-- ################ -->
    <!-- Left Leg -->
    <motor name="left_hip_pitch_joint" joint="left_hip_pitch_joint"/>
    <motor name="left_hip_roll_joint" joint="left_hip_roll_joint"/>
    <motor name="left_hip_yaw_joint" joint="left_hip_yaw_joint"/>
    <motor name="left_knee_joint" joint="left_knee_joint"/>
    <motor name="left_ankle_pitch_joint" joint="left_ankle_pitch_joint"/>
    <motor name="left_ankle_roll_joint" joint="left_ankle_roll_joint"/>

    <!-- Right Leg -->
    <motor name="right_hip_pitch_joint" joint="right_hip_pitch_joint"/>
    <motor name="right_hip_roll_joint" joint="right_hip_roll_joint"/>
    <motor name="right_hip_yaw_joint" joint="right_hip_yaw_joint"/>
    <motor name="right_knee_joint" joint="right_knee_joint"/>
    <motor name="right_ankle_pitch_joint" joint="right_ankle_pitch_joint"/>
    <motor name="right_ankle_roll_joint" joint="right_ankle_roll_joint"/>

    <!-- Waist -->
    <motor name="waist_yaw_joint" joint="waist_yaw_joint"/>
    <motor name="waist_roll_joint" joint="waist_roll_joint"/>
    <motor name="waist_pitch_joint" joint="waist_pitch_joint"/>

    <!-- Left Arm -->
    <motor name="left_shoulder_pitch_joint" joint="left_shoulder_pitch_joint"/>
    <motor name="left_shoulder_roll_joint" joint="left_shoulder_roll_joint"/>
    <motor name="left_shoulder_yaw_joint" joint="left_shoulder_yaw_joint"/>
    <motor name="left_elbow_joint" joint="left_elbow_joint"/>
    <motor name="left_wrist_roll_joint" joint="left_wrist_roll_joint"/>
    <motor name="left_wrist_pitch_joint" joint="left_wrist_pitch_joint"/>
    <motor name="left_wrist_yaw_joint" joint="left_wrist_yaw_joint"/>

    <!-- Left Hand -->
    <!-- <motor name="left_hand_thumb_0_joint" joint="left_hand_thumb_0_joint"/>
    <motor name="left_hand_thumb_1_joint" joint="left_hand_thumb_1_joint"/>
    <motor name="left_hand_thumb_2_joint" joint="left_hand_thumb_2_joint"/>
    <motor name="left_hand_middle_0_joint" joint="left_hand_middle_0_joint"/>
    <motor name="left_hand_middle_1_joint" joint="left_hand_middle_1_joint"/>
    <motor name="left_hand_index_0_joint" joint="left_hand_index_0_joint"/>
    <motor name="left_hand_index_1_joint" joint="left_hand_index_1_joint"/> -->

    <!-- Right Arm -->
    <motor name="right_shoulder_pitch_joint" joint="right_shoulder_pitch_joint"/>
    <motor name="right_shoulder_roll_joint" joint="right_shoulder_roll_joint"/>
    <motor name="right_shoulder_yaw_joint" joint="right_shoulder_yaw_joint"/>
    <motor name="right_elbow_joint" joint="right_elbow_joint"/>
    <motor name="right_wrist_roll_joint" joint="right_wrist_roll_joint"/>
    <motor name="right_wrist_pitch_joint" joint="right_wrist_pitch_joint"/>
    <motor name="right_wrist_yaw_joint" joint="right_wrist_yaw_joint"/>

    <!-- Right Hand -->
    <!-- <motor name="right_hand_thumb_0_joint" joint="right_hand_thumb_0_joint"/>
    <motor name="right_hand_thumb_1_joint" joint="right_hand_thumb_1_joint"/>
    <motor name="right_hand_thumb_2_joint" joint="right_hand_thumb_2_joint"/>
    <motor name="right_hand_index_0_joint" joint="right_hand_index_0_joint"/>
    <motor name="right_hand_index_1_joint" joint="right_hand_index_1_joint"/>
    <motor name="right_hand_middle_0_joint" joint="right_hand_middle_0_joint"/>
    <motor name="right_hand_middle_1_joint" joint="right_hand_middle_1_joint"/> -->
  </actuator>

  <sensor>
    <!-- ###################### -->
    <!-- Joint position sensors -->
    <!-- ###################### -->
    <!-- Left Leg -->
    <jointpos name="left_hip_pitch_joint_pos_sensor" joint="left_hip_pitch_joint" noise="0.001"/>
    <jointpos name="left_hip_roll_joint_pos_sensor" joint="left_hip_roll_joint" noise="0.001"/>
    <jointpos name="left_hip_yaw_joint_pos_sensor" joint="left_hip_yaw_joint" noise="0.001"/>
    <jointpos name="left_knee_joint_pos_sensor" joint="left_knee_joint" noise="0.001"/>
    <jointpos name="left_ankle_pitch_joint_pos_sensor" joint="left_ankle_pitch_joint" noise="0.001"/>
    <jointpos name="left_ankle_roll_joint_pos_sensor" joint="left_ankle_roll_joint" noise="0.001"/>

    <!-- Right Leg -->
    <jointpos name="right_hip_pitch_joint_pos_sensor" joint="right_hip_pitch_joint" noise="0.001"/>
    <jointpos name="right_hip_roll_joint_pos_sensor" joint="right_hip_roll_joint" noise="0.001"/>
    <jointpos name="right_hip_yaw_joint_pos_sensor" joint="right_hip_yaw_joint" noise="0.001"/>
    <jointpos name="right_knee_joint_pos_sensor" joint="right_knee_joint" noise="0.001"/>
    <jointpos name="right_ankle_pitch_joint_pos_sensor" joint="right_ankle_pitch_joint" noise="0.001"/>
    <jointpos name="right_ankle_roll_joint_pos_sensor" joint="right_ankle_roll_joint" noise="0.001"/>

    <!-- Waist -->
    <jointpos name="waist_yaw_joint_pos_sensor" joint="waist_yaw_joint" noise="0.001"/>
    <jointpos name="waist_roll_joint_pos_sensor" joint="waist_roll_joint" noise="0.001"/>
    <jointpos name="waist_pitch_joint_pos_sensor" joint="waist_pitch_joint" noise="0.001"/>

    <!-- Left Arm -->
    <jointpos name="left_shoulder_pitch_joint_pos_sensor" joint="left_shoulder_pitch_joint" noise="0.001"/>
    <jointpos name="left_shoulder_roll_joint_pos_sensor" joint="left_shoulder_roll_joint" noise="0.001"/>
    <jointpos name="left_shoulder_yaw_joint_pos_sensor" joint="left_shoulder_yaw_joint" noise="0.001"/>
    <jointpos name="left_elbow_joint_pos_sensor" joint="left_elbow_joint" noise="0.001"/>
    <jointpos name="left_wrist_roll_joint_pos_sensor" joint="left_wrist_roll_joint" noise="0.001"/>
    <jointpos name="left_wrist_pitch_joint_pos_sensor" joint="left_wrist_pitch_joint" noise="0.001"/>
    <jointpos name="left_wrist_yaw_joint_pos_sensor" joint="left_wrist_yaw_joint" noise="0.001"/>

    <!-- Left Hand -->
    <jointpos name="left_hand_thumb_0_joint_pos_sensor" joint="left_hand_thumb_0_joint"/>
    <jointpos name="left_hand_thumb_1_joint_pos_sensor" joint="left_hand_thumb_1_joint"/>
    <jointpos name="left_hand_thumb_2_joint_pos_sensor" joint="left_hand_thumb_2_joint"/>
    <jointpos name="left_hand_middle_0_joint_pos_sensor" joint="left_hand_middle_0_joint"/>
    <jointpos name="left_hand_middle_1_joint_pos_sensor" joint="left_hand_middle_1_joint"/>
    <jointpos name="left_hand_index_0_joint_pos_sensor" joint="left_hand_index_0_joint"/>
    <jointpos name="left_hand_index_1_joint_pos_sensor" joint="left_hand_index_1_joint"/>

    <!-- Right Arm -->
    <jointpos name="right_shoulder_pitch_joint_pos_sensor" joint="right_shoulder_pitch_joint"/>
    <jointpos name="right_shoulder_roll_joint_pos_sensor" joint="right_shoulder_roll_joint"/>
    <jointpos name="right_shoulder_yaw_joint_pos_sensor" joint="right_shoulder_yaw_joint"/>
    <jointpos name="right_elbow_joint_pos_sensor" joint="right_elbow_joint"/>
    <jointpos name="right_wrist_roll_joint_pos_sensor" joint="right_wrist_roll_joint"/>
    <jointpos name="right_wrist_pitch_joint_pos_sensor" joint="right_wrist_pitch_joint"/>
    <jointpos name="right_wrist_yaw_joint_pos_sensor" joint="right_wrist_yaw_joint"/>

    <!-- Right Hand -->
    <jointpos name="right_hand_thumb_0_joint_pos_sensor" joint="right_hand_thumb_0_joint"/>
    <jointpos name="right_hand_thumb_1_joint_pos_sensor" joint="right_hand_thumb_1_joint"/>
    <jointpos name="right_hand_thumb_2_joint_pos_sensor" joint="right_hand_thumb_2_joint"/>
    <jointpos name="right_hand_index_0_joint_pos_sensor" joint="right_hand_index_0_joint"/>
    <jointpos name="right_hand_index_1_joint_pos_sensor" joint="right_hand_index_1_joint"/>
    <jointpos name="right_hand_middle_0_joint_pos_sensor" joint="right_hand_middle_0_joint"/>
    <jointpos name="right_hand_middle_1_joint_pos_sensor" joint="right_hand_middle_1_joint"/>

    <!-- ###################### -->
    <!-- Joint velocity sensors -->
    <!-- ###################### -->
    <!-- Left Leg -->
    <jointvel name="left_hip_pitch_joint_vel_sensor" joint="left_hip_pitch_joint" noise="0.001"/>
    <jointvel name="left_hip_roll_joint_vel_sensor" joint="left_hip_roll_joint" noise="0.001"/>
    <jointvel name="left_hip_yaw_joint_vel_sensor" joint="left_hip_yaw_joint" noise="0.001"/>
    <jointvel name="left_knee_joint_vel_sensor" joint="left_knee_joint" noise="0.001"/>
    <jointvel name="left_ankle_pitch_joint_vel_sensor" joint="left_ankle_pitch_joint" noise="0.001"/>
    <jointvel name="left_ankle_roll_joint_vel_sensor" joint="left_ankle_roll_joint" noise="0.001"/>

    <!-- Right Leg -->
    <jointvel name="right_hip_pitch_joint_vel_sensor" joint="right_hip_pitch_joint" noise="0.001"/>
    <jointvel name="right_hip_roll_joint_vel_sensor" joint="right_hip_roll_joint" noise="0.001"/>
    <jointvel name="right_hip_yaw_joint_vel_sensor" joint="right_hip_yaw_joint" noise="0.001"/>
    <jointvel name="right_knee_joint_vel_sensor" joint="right_knee_joint" noise="0.001"/>
    <jointvel name="right_ankle_pitch_joint_vel_sensor" joint="right_ankle_pitch_joint" noise="0.001"/>
    <jointvel name="right_ankle_roll_joint_vel_sensor" joint="right_ankle_roll_joint" noise="0.001"/>

    <!-- Waist -->
    <jointvel name="waist_yaw_joint_vel_sensor" joint="waist_yaw_joint" noise="0.001"/>
    <jointvel name="waist_roll_joint_vel_sensor" joint="waist_roll_joint" noise="0.001"/>
    <jointvel name="waist_pitch_joint_vel_sensor" joint="waist_pitch_joint" noise="0.001"/>

    <!-- Left Arm -->
    <jointvel name="left_shoulder_pitch_joint_vel_sensor" joint="left_shoulder_pitch_joint" noise="0.001"/>
    <jointvel name="left_shoulder_roll_joint_vel_sensor" joint="left_shoulder_roll_joint" noise="0.001"/>
    <jointvel name="left_shoulder_yaw_joint_vel_sensor" joint="left_shoulder_yaw_joint" noise="0.001"/>
    <jointvel name="left_elbow_joint_vel_sensor" joint="left_elbow_joint" noise="0.001"/>
    <jointvel name="left_wrist_roll_joint_vel_sensor" joint="left_wrist_roll_joint" noise="0.001"/>
    <jointvel name="left_wrist_pitch_joint_vel_sensor" joint="left_wrist_pitch_joint" noise="0.001"/>
    <jointvel name="left_wrist_yaw_joint_vel_sensor" joint="left_wrist_yaw_joint" noise="0.001"/>

    <!-- Left Hand -->
    <jointvel name="left_hand_thumb_0_joint_vel_sensor" joint="left_hand_thumb_0_joint"/>
    <jointvel name="left_hand_thumb_1_joint_vel_sensor" joint="left_hand_thumb_1_joint"/>
    <jointvel name="left_hand_thumb_2_joint_vel_sensor" joint="left_hand_thumb_2_joint"/>
    <jointvel name="left_hand_middle_0_joint_vel_sensor" joint="left_hand_middle_0_joint"/>
    <jointvel name="left_hand_middle_1_joint_vel_sensor" joint="left_hand_middle_1_joint"/>
    <jointvel name="left_hand_index_0_joint_vel_sensor" joint="left_hand_index_0_joint"/>
    <jointvel name="left_hand_index_1_joint_vel_sensor" joint="left_hand_index_1_joint"/>

    <!-- Right Arm -->
    <jointvel name="right_shoulder_pitch_joint_vel_sensor" joint="right_shoulder_pitch_joint"/>
    <jointvel name="right_shoulder_roll_joint_vel_sensor" joint="right_shoulder_roll_joint"/>
    <jointvel name="right_shoulder_yaw_joint_vel_sensor" joint="right_shoulder_yaw_joint"/>
    <jointvel name="right_elbow_joint_vel_sensor" joint="right_elbow_joint"/>
    <jointvel name="right_wrist_roll_joint_vel_sensor" joint="right_wrist_roll_joint"/>
    <jointvel name="right_wrist_pitch_joint_vel_sensor" joint="right_wrist_pitch_joint"/>
    <jointvel name="right_wrist_yaw_joint_vel_sensor" joint="right_wrist_yaw_joint"/>

    <!-- Right Hand -->
    <jointvel name="right_hand_thumb_0_joint_vel_sensor" joint="right_hand_thumb_0_joint"/>
    <jointvel name="right_hand_thumb_1_joint_vel_sensor" joint="right_hand_thumb_1_joint"/>
    <jointvel name="right_hand_thumb_2_joint_vel_sensor" joint="right_hand_thumb_2_joint"/>
    <jointvel name="right_hand_index_0_joint_vel_sensor" joint="right_hand_index_0_joint"/>
    <jointvel name="right_hand_index_1_joint_vel_sensor" joint="right_hand_index_1_joint"/>
    <jointvel name="right_hand_middle_0_joint_vel_sensor" joint="right_hand_middle_0_joint"/>
    <jointvel name="right_hand_middle_1_joint_vel_sensor" joint="right_hand_middle_1_joint"/>


    <!-- IMU sensors -->
    <accelerometer name="imu_acc_sensor" site="imu" noise="0.1"/>
    <gyro name="imu_gyro_sensor" site="imu" noise="0.01"/>
    <framequat name="imu_quat_sensor" objtype="site" objname="imu" noise="0.01"/>

    <!-- Mocap sensors -->
    <framepos name="base_mocap_pos_sensor" objtype="site" objname="torso_mocap_site" noise="0.01"/>
    <framequat name="base_mocap_quat_sensor" objtype="site" objname="torso_mocap_site" noise="0.01"/>
  </sensor>

  <keyframe>
    <!-- <key name="standing"
      qpos="-0.3 0 0 0.52 -0.23 0
            -0.3 0 0 0.52 -0.23 0
            0 0 0.03
            0 0 0 0.2 0 0 0
            0 0 0 0 0 0 0
            0 0 0 0.2 0 0 0
            0 0 0 0 0 0 0"
      ctrl="-0.3 0 0 0.52 -0.23 0
            -0.3 0 0 0.52 -0.23 0
            0 0 0
            0 0 0 0.2 0 0 0
            0 0 0 0 0 0 0
            0 0 0 0.2 0 0 0
            0 0 0 0 0 0 0

            0 0 0 0 0 0
            0 0 0 0 0 0
            0 0 0
            0 0 0 0 0 0 0
            0 0 0 0 0 0 0
            0 0 0 0 0 0 0
            0 0 0 0 0 0 0

            0 0 0 0 0 0
            0 0 0 0 0 0
            0 0 0
            0 0 0 0 0 0 0
            0 0 0 0 0 0 0
            0 0 0 0 0 0 0
            0 0 0 0 0 0 0"/> -->
    <key name="standing"
      qpos="-0.3 0 0 0.52 -0.23 0
            -0.3 0 0 0.52 -0.23 0
            0 0 0.03
            0 0 0 0.2 0 0 0
            0 0 0 0 0 0 0
            0 0 0 0.2 0 0 0
            0 0 0 0 0 0 0"
      ctrl="-0.3 0 0 0.52 -0.23 0
            -0.3 0 0 0.52 -0.23 0
            0 0 0
            0 0 0 0.2 0 0 0
            0 0 0 0.2 0 0 0

            0 0 0 0 0 0
            0 0 0 0 0 0
            0 0 0
            0 0 0 0 0 0 0
            0 0 0 0 0 0 0

            0 0 0 0 0 0
            0 0 0 0 0 0
            0 0 0
            0 0 0 0 0 0 0
            0 0 0 0 0 0 0"/>
    <!-- <key name="home" qpos="0 0 0.27 1 0 0 0 0 0.9 -1.8 0 0.9 -1.8 0 0.9 -1.8 0 0.9 -1.8"
      ctrl="0 0.9 -1.8 0 0.9 -1.8 0 0.9 -1.8 0 0.9 -1.8"/> -->
  </keyframe>

  <!-- setup scene -->
  <!-- <statistic center="1.0 0.7 1.0" extent="0.8"/>
  <visual>
    <headlight diffuse="0.6 0.6 0.6" ambient="0.1 0.1 0.1" specular="0.9 0.9 0.9"/>
    <rgba haze="0.15 0.25 0.35 1"/>
    <global azimuth="-140" elevation="-20"/>
  </visual>
  <asset>
    <texture type="skybox" builtin="flat" rgb1="0 0 0" rgb2="0 0 0" width="512" height="3072"/>
    <texture type="2d" name="groundplane" builtin="checker" mark="edge" rgb1="0.2 0.3 0.4" rgb2="0.1 0.2 0.3" markrgb="0.8 0.8 0.8" width="300" height="300"/>
    <material name="groundplane" texture="groundplane" texuniform="true" texrepeat="5 5" reflectance="0.2"/>
  </asset>
  <worldbody>
    <light pos="1 0 3.5" dir="0 0 -1" directional="true"/>
    <geom name="floor" size="0 0 0.05" type="plane" material="groundplane"/>
  </worldbody> -->
</mujoco>
