<?xml version="1.0" encoding="utf-8" ?>
<!-- =================================================================================== -->
<!-- |    This document was autogenerated by csv to urdf                               | -->
<!-- |    EDITING THIS FILE BY HAND IS NOT RECOMMENDED                                 | -->
<!-- =================================================================================== -->
<robot
  name="TH02-A7">
  <link
    name="BASE_LINK">
    <inertial>
      <origin
        xyz="-0.08171 7.40E-05 -0.01979"
        rpy="0 0 0" />
      <mass
        value="12.72953" />
      <inertia
        ixx="0.257062"
        ixy="-0.000133"
        ixz="0.031411"
        iyy="0.316902"
        iyz="0.000321"
        izz="0.173619" />
    </inertial>
    <visual>
      <origin
        xyz="0 0 0"
        rpy="0 0 0" />
      <geometry>
        <mesh
          filename="package://themis_description/meshes/BASE_LINK.STL" />
      </geometry>
      <material
        name="">
        <color
          rgba="0.792156863 0.819607843 0.933333333 1" />
      </material>
    </visual>
    <collision>
      <origin
        xyz="0 0 0"
        rpy="0 0 0" />
      <geometry>
        <mesh
          filename="package://themis_description/meshes/BASE_LINK.STL" />
      </geometry>
    </collision>
  </link>
  <link
    name="HIP_R">
    <inertial>
      <origin
        xyz="0.00398 -0.00006 0.00636"
        rpy="0 0 0" />
      <mass
        value="0.83264" />
      <inertia
        ixx="0.0019"
        ixy="0"
        ixz="0"
        iyy="0.00124"
        iyz="0"
        izz="0.00094" />
    </inertial>
    <visual>
      <origin
        xyz="0 0 0"
        rpy="0 0 0" />
      <geometry>
        <mesh
          filename="package://themis_description/meshes/HIP_R.STL" />
      </geometry>
      <material
        name="">
        <color
          rgba="0.792156863 0.819607843 0.933333333 1" />
      </material>
    </visual>
    <collision>
      <origin
        xyz="0 0 0"
        rpy="0 0 0" />
      <geometry>
        <mesh
          filename="package://themis_description/meshes/HIP_R.STL" />
      </geometry>
    </collision>
  </link>
  <joint
    name="HIP_YAW_R"
    type="revolute">
    <origin
      xyz="-0.18337794 -0.0625 -0.28837794"
      rpy="0 0.785398163 0" />
    <parent
      link="BASE_LINK" />
    <child
      link="HIP_R" />
    <axis
      xyz="0 0 1" />
    <limit
      command_effort="150"
      lower="-1.4"
      upper="1.4"
      effort="150"
      velocity="30" />
  </joint>
  <link
    name="HIP_ABAD_R">
    <inertial>
      <origin
        xyz="-0.002 0.00147 0.00404"
        rpy="0 0 0" />
      <mass
        value="2.78794" />
      <inertia
        ixx="0.01442"
        ixy="0"
        ixz="-0.00002"
        iyy="0.00791"
        iyz="0"
        izz="0.0072" />
    </inertial>
    <visual>
      <origin
        xyz="0 0 0"
        rpy="0 0 0" />
      <geometry>
        <mesh
          filename="package://themis_description/meshes/HIP_ABAD_R.STL" />
      </geometry>
      <material
        name="">
        <color
          rgba="0.792156863 0.819607843 0.933333333 1" />
      </material>
    </visual>
    <collision>
      <origin
        xyz="0 0 0"
        rpy="0 0 0" />
      <geometry>
        <mesh
          filename="package://themis_description/meshes/HIP_ABAD_R.STL" />
      </geometry>
    </collision>
  </link>
  <joint
    name="HIP_ROLL_R"
    type="revolute">
    <origin
      xyz="0.141 0 0"
      rpy="1.570796327 0 -1.570796327" />
    <parent
      link="HIP_R" />
    <child
      link="HIP_ABAD_R" />
    <axis
      xyz="0 0 1" />
    <limit
      command_effort="150"
      lower="-1.4"
      upper="1.4"
      effort="150"
      velocity="30" />
  </joint>
  <link
    name="FEMUR_R">
    <inertial>
      <origin
        xyz="0.06111 0.00174 0.02002"
        rpy="0 0 0" />
      <mass
        value="3.75384" />
      <inertia
        ixx="0.01172"
        ixy="0.00157"
        ixz="0.00098"
        iyy="0.07026"
        iyz="0.00014"
        izz="0.07594" />
    </inertial>
    <visual>
      <origin
        xyz="0 0 0"
        rpy="0 0 0" />
      <geometry>
        <mesh
          filename="package://themis_description/meshes/FEMUR_R.STL" />
      </geometry>
      <material
        name="">
        <color
          rgba="0.792156863 0.819607843 0.933333333 1" />
      </material>
    </visual>
    <collision>
      <origin
        xyz="0 0 0"
        rpy="0 0 0" />
      <geometry>
        <mesh
          filename="package://themis_description/meshes/FEMUR_R.STL" />
      </geometry>
    </collision>
  </link>
  <joint
    name="HIP_PITCH_R"
    type="revolute">
    <origin
      xyz="0.029 0 0"
      rpy="-1.570796327 0.785398163 -1.570796327" />
    <parent
      link="HIP_ABAD_R" />
    <child
      link="FEMUR_R" />
    <axis
      xyz="0 0 1" />
    <limit
      command_effort="150"
      lower="-1.4"
      upper="1.4"
      effort="150"
      velocity="30" />
  </joint>
  <link
    name="TIBIA_R">
    <inertial>
      <origin
        xyz="0.09678 0.00694 -0.00006"
        rpy="0 0 0" />
      <mass
        value="1.27716" />
      <inertia
        ixx="0.00091"
        ixy="0.00069"
        ixz="-0.00001"
        iyy="0.02323"
        iyz="0"
        izz="0.02318" />
    </inertial>
    <visual>
      <origin
        xyz="0 0 0"
        rpy="0 0 0" />
      <geometry>
        <mesh
          filename="package://themis_description/meshes/TIBIA_R.STL" />
      </geometry>
      <material
        name="">
        <color
          rgba="0.792156863 0.819607843 0.933333333 1" />
      </material>
    </visual>
    <collision>
      <origin
        xyz="0 0 0"
        rpy="0 0 0" />
      <geometry>
        <mesh
          filename="package://themis_description/meshes/TIBIA_R.STL" />
      </geometry>
    </collision>
  </link>
  <joint
    name="KNEE_PITCH_R"
    type="revolute">
    <origin
      xyz="0.375 0 0"
      rpy="0 0 0" />
    <parent
      link="FEMUR_R" />
    <child
      link="TIBIA_R" />
    <axis
      xyz="0 0 1" />
    <limit
      command_effort="150"
      lower="-2.4"
      upper="-0.1"
      effort="150"
      velocity="30" />
  </joint>
  <link
    name="ANKLE_R">
    <inertial>
      <origin
        xyz="0 0 0"
        rpy="0 0 0" />
      <mass
        value="0.01" />
      <inertia
        ixx="0.001"
        ixy="0"
        ixz="0"
        iyy="0.001"
        iyz="0"
        izz="0.001" />
    </inertial>
    <visual>
      <origin
        xyz="0 0 0"
        rpy="0 0 0" />
      <geometry>
        <mesh
          filename="package://themis_description/meshes/ANKLE_R.STL" />
      </geometry>
      <material
        name="">
        <color
          rgba="0.792156863 0.819607843 0.933333333 1" />
      </material>
    </visual>
    <collision>
      <origin
        xyz="0 0 0"
        rpy="0 0 0" />
      <geometry>
        <mesh
          filename="package://themis_description/meshes/ANKLE_R.STL" />
      </geometry>
    </collision>
  </link>
  <joint
    name="ANKLE_PITCH_R"
    type="revolute">
    <origin
      xyz="0.375 0 0"
      rpy="0 0 0" />
    <parent
      link="TIBIA_R" />
    <child
      link="ANKLE_R" />
    <axis
      xyz="0 0 1" />
    <limit
      command_effort="35"
      lower="-1"
      upper="1.5"
      effort="35"
      velocity="30" />
  </joint>
  <link
    name="FOOT_R">
    <inertial>
      <origin
        xyz="0.0337 5.00E-05 0.04684"
        rpy="0 0 0" />
      <mass
        value="0.41628" />
      <inertia
        ixx="0.002594"
        ixy="9.89E-07"
        ixz="0.000725"
        iyy="0.002998"
        iyz="1.24E-06"
        izz="0.000722" />
    </inertial>
    <visual>
      <origin
        xyz="0 0 0"
        rpy="0 0 0" />
      <geometry>
        <mesh
          filename="package://themis_description/meshes/FOOT_R.STL" />
      </geometry>
      <material
        name="">
        <color
          rgba="0.792156863 0.819607843 0.933333333 1" />
      </material>
    </visual>
    <collision>
      <origin
        xyz="0 0 0"
        rpy="0 0 0" />
      <geometry>
        <mesh
          filename="package://themis_description/meshes/FOOT_R.STL" />
      </geometry>
    </collision>
  </link>
  <joint
    name="ANKLE_ROLL_R"
    type="revolute">
    <origin
      xyz="0 0 0"
      rpy="-1.570796327 0 0" />
    <parent
      link="ANKLE_R" />
    <child
      link="FOOT_R" />
    <axis
      xyz="0 0 1" />
    <limit
      command_effort="35"
      lower="-0.3"
      upper="0.3"
      effort="35"
      velocity="30" />
  </joint>
  <link
    name="HIP_L">
    <inertial>
      <origin
        xyz="0.00398 -0.00006 0.00636"
        rpy="0 0 0" />
      <mass
        value="0.83264" />
      <inertia
        ixx="0.0019"
        ixy="0"
        ixz="0"
        iyy="0.00124"
        iyz="0"
        izz="0.00094" />
    </inertial>
    <visual>
      <origin
        xyz="0 0 0"
        rpy="0 0 0" />
      <geometry>
        <mesh
          filename="package://themis_description/meshes/HIP_L.STL" />
      </geometry>
      <material
        name="">
        <color
          rgba="0.792156863 0.819607843 0.933333333 1" />
      </material>
    </visual>
    <collision>
      <origin
        xyz="0 0 0"
        rpy="0 0 0" />
      <geometry>
        <mesh
          filename="package://themis_description/meshes/HIP_L.STL" />
      </geometry>
    </collision>
  </link>
  <joint
    name="HIP_YAW_L"
    type="revolute">
    <origin
      xyz="-0.18337794 0.0625 -0.28837794"
      rpy="0 0.785398163 0" />
    <parent
      link="BASE_LINK" />
    <child
      link="HIP_L" />
    <axis
      xyz="0 0 1" />
    <limit
      command_effort="150"
      lower="-1.4"
      upper="1.4"
      effort="150"
      velocity="30" />
  </joint>
  <link
    name="HIP_ABAD_L">
    <inertial>
      <origin
        xyz="0.00198 0.00146 0.00395"
        rpy="0 0 0" />
      <mass
        value="2.818" />
      <inertia
        ixx="0.01442"
        ixy="0"
        ixz="0.00002"
        iyy="0.00791"
        iyz="0"
        izz="0.0072" />
    </inertial>
    <visual>
      <origin
        xyz="0 0 0"
        rpy="0 0 0" />
      <geometry>
        <mesh
          filename="package://themis_description/meshes/HIP_ABAD_L.STL" />
      </geometry>
      <material
        name="">
        <color
          rgba="0.792156863 0.819607843 0.933333333 1" />
      </material>
    </visual>
    <collision>
      <origin
        xyz="0 0 0"
        rpy="0 0 0" />
      <geometry>
        <mesh
          filename="package://themis_description/meshes/HIP_ABAD_L.STL" />
      </geometry>
    </collision>
  </link>
  <joint
    name="HIP_ROLL_L"
    type="revolute">
    <origin
      xyz="0.141 0 0"
      rpy="1.570796327 0 -1.570796327" />
    <parent
      link="HIP_L" />
    <child
      link="HIP_ABAD_L" />
    <axis
      xyz="0 0 1" />
    <limit
      command_effort="150"
      lower="-1.4"
      upper="1.4"
      effort="150"
      velocity="30" />
  </joint>
  <link
    name="FEMUR_L">
    <inertial>
      <origin
        xyz="0.06112 0.00177 -0.02002"
        rpy="0 0 0" />
      <mass
        value="3.75393" />
      <inertia
        ixx="0.01172"
        ixy="0.00157"
        ixz="-0.00098"
        iyy="0.07027"
        iyz="-0.00014"
        izz="0.07595" />
    </inertial>
    <visual>
      <origin
        xyz="0 0 0"
        rpy="0 0 0" />
      <geometry>
        <mesh
          filename="package://themis_description/meshes/FEMUR_L.STL" />
      </geometry>
      <material
        name="">
        <color
          rgba="0.792156863 0.819607843 0.933333333 1" />
      </material>
    </visual>
    <collision>
      <origin
        xyz="0 0 0"
        rpy="0 0 0" />
      <geometry>
        <mesh
          filename="package://themis_description/meshes/FEMUR_L.STL" />
      </geometry>
    </collision>
  </link>
  <joint
    name="HIP_PITCH_L"
    type="revolute">
    <origin
      xyz="-0.029 0 0"
      rpy="-1.570796327 0.785398163 -1.570796327" />
    <parent
      link="HIP_ABAD_L" />
    <child
      link="FEMUR_L" />
    <axis
      xyz="0 0 1" />
    <limit
      command_effort="150"
      lower="-1.4"
      upper="1.4"
      effort="150"
      velocity="30" />
  </joint>
  <link
    name="TIBIA_L">
    <inertial>
      <origin
        xyz="0.09678 0.00694 -0.00006"
        rpy="0 0 0" />
      <mass
        value="1.27716" />
      <inertia
        ixx="0.00091"
        ixy="0.00069"
        ixz="-0.00001"
        iyy="0.02323"
        iyz="0"
        izz="0.02318" />
    </inertial>
    <visual>
      <origin
        xyz="0 0 0"
        rpy="0 0 0" />
      <geometry>
        <mesh
          filename="package://themis_description/meshes/TIBIA_L.STL" />
      </geometry>
      <material
        name="">
        <color
          rgba="0.792156863 0.819607843 0.933333333 1" />
      </material>
    </visual>
    <collision>
      <origin
        xyz="0 0 0"
        rpy="0 0 0" />
      <geometry>
        <mesh
          filename="package://themis_description/meshes/TIBIA_L.STL" />
      </geometry>
    </collision>
  </link>
  <joint
    name="KNEE_PITCH_L"
    type="revolute">
    <origin
      xyz="0.375 0 0"
      rpy="0 0 0" />
    <parent
      link="FEMUR_L" />
    <child
      link="TIBIA_L" />
    <axis
      xyz="0 0 1" />
    <limit
      command_effort="150"
      lower="-2.4"
      upper="-0.1"
      effort="150"
      velocity="30" />
  </joint>
  <link
    name="ANKLE_L">
    <inertial>
      <origin
        xyz="0 0 0"
        rpy="0 0 0" />
      <mass
        value="0.01" />
      <inertia
        ixx="0.001"
        ixy="0"
        ixz="0"
        iyy="0.001"
        iyz="0"
        izz="0.001" />
    </inertial>
    <visual>
      <origin
        xyz="0 0 0"
        rpy="0 0 0" />
      <geometry>
        <mesh
          filename="package://themis_description/meshes/ANKLE_L.STL" />
      </geometry>
      <material
        name="">
        <color
          rgba="0.792156863 0.819607843 0.933333333 1" />
      </material>
    </visual>
    <collision>
      <origin
        xyz="0 0 0"
        rpy="0 0 0" />
      <geometry>
        <mesh
          filename="package://themis_description/meshes/ANKLE_L.STL" />
      </geometry>
    </collision>
  </link>
  <joint
    name="ANKLE_PITCH_L"
    type="revolute">
    <origin
      xyz="0.375 0 0"
      rpy="0 0 0" />
    <parent
      link="TIBIA_L" />
    <child
      link="ANKLE_L" />
    <axis
      xyz="0 0 1" />
    <limit
      command_effort="35"
      lower="-1"
      upper="1.5"
      effort="35"
      velocity="30" />
  </joint>
  <link
    name="FOOT_L">
    <inertial>
      <origin
        xyz="0.0337 5.00E-05 0.04684"
        rpy="0 0 0" />
      <mass
        value="0.41628" />
      <inertia
        ixx="0.002594"
        ixy="9.89E-07"
        ixz="0.000725"
        iyy="0.002998"
        iyz="1.24E-06"
        izz="0.000722" />
    </inertial>
    <visual>
      <origin
        xyz="0 0 0"
        rpy="0 0 0" />
      <geometry>
        <mesh
          filename="package://themis_description/meshes/FOOT_L.STL" />
      </geometry>
      <material
        name="">
        <color
          rgba="0.792156863 0.819607843 0.933333333 1" />
      </material>
    </visual>
    <collision>
      <origin
        xyz="0 0 0"
        rpy="0 0 0" />
      <geometry>
        <mesh
          filename="package://themis_description/meshes/FOOT_L.STL" />
      </geometry>
    </collision>
  </link>
  <joint
    name="ANKLE_ROLL_L"
    type="revolute">
    <origin
      xyz="0 0 0"
      rpy="-1.570796327 0 0" />
    <parent
      link="ANKLE_L" />
    <child
      link="FOOT_L" />
    <axis
      xyz="0 0 1" />
    <limit
      command_effort="35"
      lower="-0.3"
      upper="0.3"
      effort="35"
      velocity="30" />
  </joint>
  <link
    name="UPPERSHOULDER_R">
    <inertial>
      <origin
        xyz="0.00158 0.00121 -0.00674"
        rpy="0 0 0" />
      <mass
        value="0.43611" />
      <inertia
        ixx="0.000385927"
        ixy="-2.60E-07"
        ixz="9.81E-07"
        iyy="0.000304132"
        iyz="5.57E-06"
        izz="0.000234707" />
    </inertial>
    <visual>
      <origin
        xyz="0 0 0"
        rpy="0 0 0" />
      <geometry>
        <mesh
          filename="package://themis_description/meshes/UPPERSHOULDER_R.STL" />
      </geometry>
      <material
        name="">
        <color
          rgba="0.792156863 0.819607843 0.933333333 1" />
      </material>
    </visual>
    <collision>
      <origin
        xyz="0 0 0"
        rpy="0 0 0" />
      <geometry>
        <mesh
          filename="package://themis_description/meshes/UPPERSHOULDER_R.STL" />
      </geometry>
    </collision>
  </link>
  <joint
    name="SHOULDER_PITCH_R"
    type="revolute">
    <origin
      xyz="-0.065084608 -0.1567 0.113474882"
      rpy="1.570796327 0 0" />
    <parent
      link="BASE_LINK" />
    <child
      link="UPPERSHOULDER_R" />
    <axis
      xyz="0 0 1" />
    <limit
      command_effort="50"
      lower="-3.1416"
      upper="3.1416"
      effort="50"
      velocity="30" />
  </joint>
  <link
    name="LOWERSHOULDER_R">
    <inertial>
      <origin
        xyz="0.0535 -6.00E-05 2.00E-05"
        rpy="0 0 0" />
      <mass
        value="0.35798" />
      <inertia
        ixx="0.000261"
        ixy="-1.67E-06"
        ixz="2.50E-07"
        iyy="0.001315"
        iyz="-1.55E-08"
        izz="0.001242" />
    </inertial>
    <visual>
      <origin
        xyz="0 0 0"
        rpy="0 0 0" />
      <geometry>
        <mesh
          filename="package://themis_description/meshes/LOWERSHOULDER_R.STL" />
      </geometry>
      <material
        name="">
        <color
          rgba="0.792156863 0.819607843 0.933333333 1" />
      </material>
    </visual>
    <collision>
      <origin
        xyz="0 0 0"
        rpy="0 0 0" />
      <geometry>
        <mesh
          filename="package://themis_description/meshes/LOWERSHOULDER_R.STL" />
      </geometry>
    </collision>
  </link>
  <joint
    name="SHOULDER_ROLL_R"
    type="revolute">
    <origin
      xyz="0 0 0"
      rpy="0 -1.570796327 3.141592653" />
    <parent
      link="UPPERSHOULDER_R" />
    <child
      link="LOWERSHOULDER_R" />
    <axis
      xyz="0 0 1" />
    <limit
      command_effort="28"
      lower="-1.6"
      upper="1.6"
      effort="28"
      velocity="30" />
  </joint>
  <link
    name="UPPERARM_R">
    <inertial>
      <origin
        xyz="-0.00152 -0.0104 0.1973"
        rpy="0 0 0" />
      <mass
        value="0.51544" />
      <inertia
        ixx="0.021671894"
        ixy="1.03E-05"
        ixz="-0.0001758"
        iyy="0.021508856"
        iyz="-0.001195001"
        izz="0.000365708" />
    </inertial>
    <visual>
      <origin
        xyz="0 0 0"
        rpy="0 0 0" />
      <geometry>
        <mesh
          filename="package://themis_description/meshes/UPPERARM_R.STL" />
      </geometry>
      <material
        name="">
        <color
          rgba="0.792156863 0.819607843 0.933333333 1" />
      </material>
    </visual>
    <collision>
      <origin
        xyz="0 0 0"
        rpy="0 0 0" />
      <geometry>
        <mesh
          filename="package://themis_description/meshes/UPPERARM_R.STL" />
      </geometry>
    </collision>
  </link>
  <joint
    name="SHOULDER_YAW_R"
    type="revolute">
    <origin
      xyz="0 0 0"
      rpy="0 -1.570796327 3.141592653" />
    <parent
      link="LOWERSHOULDER_R" />
    <child
      link="UPPERARM_R" />
    <axis
      xyz="0 0 1" />
    <limit
      command_effort="28"
      lower="-3.1416"
      upper="3.1416"
      effort="28"
      velocity="30" />
  </joint>
  <link
    name="ELBOW_R">
    <inertial>
      <origin
        xyz="0.05387 -0.01441 1.00E-05"
        rpy="0 0 0" />
      <mass
        value="0.37853" />
      <inertia
        ixx="0.000368755"
        ixy="-0.000307924"
        ixz="-2.21E-07"
        iyy="0.001430606"
        iyz="-3.69E-07"
        izz="0.00143177" />
    </inertial>
    <visual>
      <origin
        xyz="0 0 0"
        rpy="0 0 0" />
      <geometry>
        <mesh
          filename="package://themis_description/meshes/ELBOW_R.STL" />
      </geometry>
      <material
        name="">
        <color
          rgba="0.792156863 0.819607843 0.933333333 1" />
      </material>
    </visual>
    <collision>
      <origin
        xyz="0 0 0"
        rpy="0 0 0" />
      <geometry>
        <mesh
          filename="package://themis_description/meshes/ELBOW_R.STL" />
      </geometry>
    </collision>
  </link>
  <joint
    name="ELBOW_PITCH_R"
    type="revolute">
    <origin
      xyz="0 -0.015 0.22495"
      rpy="0 -1.570796327 3.141592653" />
    <parent
      link="UPPERARM_R" />
    <child
      link="ELBOW_R" />
    <axis
      xyz="0 0 1" />
    <limit
      command_effort="28"
      lower="-3.1416"
      upper="3.1416"
      effort="28"
      velocity="30" />
  </joint>
  <link
    name="FOREARM_R">
    <inertial>
      <origin
        xyz="-0.00164 1.00E-05 -0.01407"
        rpy="0 0 0" />
      <mass
        value="0.47694" />
      <inertia
        ixx="0.000684321"
        ixy="-2.15E-07"
        ixz="4.70E-06"
        iyy="0.000600813"
        iyz="-1.32E-07"
        izz="0.000265071" />
    </inertial>
    <visual>
      <origin
        xyz="0 0 0"
        rpy="0 0 0" />
      <geometry>
        <mesh
          filename="package://themis_description/meshes/FOREARM_R.STL" />
      </geometry>
      <material
        name="">
        <color
          rgba="0.792156863 0.819607843 0.933333333 1" />
      </material>
    </visual>
    <collision>
      <origin
        xyz="0 0 0"
        rpy="0 0 0" />
      <geometry>
        <mesh
          filename="package://themis_description/meshes/FOREARM_R.STL" />
      </geometry>
    </collision>
  </link>
  <joint
    name="ELBOW_YAW_R"
    type="revolute">
    <origin
      xyz="0.154950006 -0.015000026 0"
      rpy="0 -1.570796327 3.141592653" />
    <parent
      link="ELBOW_R" />
    <child
      link="FOREARM_R" />
    <axis
      xyz="0 0 1" />
    <limit
      command_effort="28"
      lower="-3.1416"
      upper="3.1416"
      effort="28"
      velocity="30" />
  </joint>
  <link
    name="UPPERWRIST_R">
    <inertial>
      <origin
        xyz="0.05463 -0.00013 9.00E-05"
        rpy="0 0 0" />
      <mass
        value="0.37004" />
      <inertia
        ixx="0.000277159"
        ixy="-3.87E-06"
        ixz="2.51E-06"
        iyy="0.001412655"
        iyz="5.51E-08"
        izz="0.001337476" />
    </inertial>
    <visual>
      <origin
        xyz="0 0 0"
        rpy="0 0 0" />
      <geometry>
        <mesh
          filename="package://themis_description/meshes/UPPERWRIST_R.STL" />
      </geometry>
      <material
        name="">
        <color
          rgba="0.792156863 0.819607843 0.933333333 1" />
      </material>
    </visual>
    <collision>
      <origin
        xyz="0 0 0"
        rpy="0 0 0" />
      <geometry>
        <mesh
          filename="package://themis_description/meshes/UPPERWRIST_R.STL" />
      </geometry>
    </collision>
  </link>
  <joint
    name="WRIST_PITCH_R"
    type="revolute">
    <origin
      xyz="0 0 0"
      rpy="3.141592653 -1.570796327 0" />
    <parent
      link="FOREARM_R" />
    <child
      link="UPPERWRIST_R" />
    <axis
      xyz="0 0 1" />
    <limit
      command_effort="28"
      lower="-3.1416"
      upper="3.1416"
      effort="28"
      velocity="30" />
  </joint>
  <link
    name="LOWERWRIST_R">
    <inertial>
      <origin
        xyz="0 2.42E-06 0.00010824"
        rpy="0 0 0" />
      <mass
        value="0.42" />
      <inertia
        ixx="0.001"
        ixy="0"
        ixz="0"
        iyy="0.001"
        iyz="0"
        izz="0.001" />
    </inertial>
    <visual>
      <origin
        xyz="0 0 0"
        rpy="0 0 0" />
      <geometry>
        <mesh
          filename="package://themis_description/meshes/LOWERWRIST_R.STL" />
      </geometry>
      <material
        name="">
        <color
          rgba="0.792156863 0.819607843 0.933333333 1" />
      </material>
    </visual>
    <collision>
      <origin
        xyz="0 0 0"
        rpy="0 0 0" />
      <geometry>
        <mesh
          filename="package://themis_description/meshes/LOWERWRIST_R.STL" />
      </geometry>
    </collision>
  </link>
  <joint
    name="WRIST_YAW_R"
    type="revolute">
    <origin
      xyz="0 0 0"
      rpy="3.141592653 -1.570796327 0" />
    <parent
      link="UPPERWRIST_R" />
    <child
      link="LOWERWRIST_R" />
    <axis
      xyz="0 0 1" />
    <limit
      command_effort="28"
      lower="-3.1416"
      upper="3.1416"
      effort="28"
      velocity="30" />
  </joint>
  <link
    name="UPPERSHOULDER_L">
    <inertial>
      <origin
        xyz="0.00158 0.00123 0.00673"
        rpy="0 0 0" />
      <mass
        value="0.43611" />
      <inertia
        ixx="0.000385927"
        ixy="-3.28E-07"
        ixz="-9.42E-07"
        iyy="0.000304104"
        iyz="-5.56E-06"
        izz="0.000234735" />
    </inertial>
    <visual>
      <origin
        xyz="0 0 0"
        rpy="0 0 0" />
      <geometry>
        <mesh
          filename="package://themis_description/meshes/UPPERSHOULDER_L.STL" />
      </geometry>
      <material
        name="">
        <color
          rgba="0.792156863 0.819607843 0.933333333 1" />
      </material>
    </visual>
    <collision>
      <origin
        xyz="0 0 0"
        rpy="0 0 0" />
      <geometry>
        <mesh
          filename="package://themis_description/meshes/UPPERSHOULDER_L.STL" />
      </geometry>
    </collision>
  </link>
  <joint
    name="SHOULDER_PITCH_L"
    type="revolute">
    <origin
      xyz="-0.065084608 0.1567 0.113474882"
      rpy="1.570796327 0 0" />
    <parent
      link="BASE_LINK" />
    <child
      link="UPPERSHOULDER_L" />
    <axis
      xyz="0 0 1" />
    <limit
      command_effort="50"
      lower="-3.1416"
      upper="3.1416"
      effort="50"
      velocity="30" />
  </joint>
  <link
    name="LOWERSHOULDER_L">
    <inertial>
      <origin
        xyz="0.0535 6.00E-05 -2.00E-05"
        rpy="0 0 0" />
      <mass
        value="0.35798" />
      <inertia
        ixx="0.000261"
        ixy="1.67E-06"
        ixz="-2.50E-07"
        iyy="0.001315"
        iyz="-1.55E-08"
        izz="0.001242" />
    </inertial>
    <visual>
      <origin
        xyz="0 0 0"
        rpy="0 0 0" />
      <geometry>
        <mesh
          filename="package://themis_description/meshes/LOWERSHOULDER_L.STL" />
      </geometry>
      <material
        name="">
        <color
          rgba="0.792156863 0.819607843 0.933333333 1" />
      </material>
    </visual>
    <collision>
      <origin
        xyz="0 0 0"
        rpy="0 0 0" />
      <geometry>
        <mesh
          filename="package://themis_description/meshes/LOWERSHOULDER_L.STL" />
      </geometry>
    </collision>
  </link>
  <joint
    name="SHOULDER_ROLL_L"
    type="revolute">
    <origin
      xyz="0 0 0"
      rpy="0 1.570796327 0" />
    <parent
      link="UPPERSHOULDER_L" />
    <child
      link="LOWERSHOULDER_L" />
    <axis
      xyz="0 0 1" />
    <limit
      command_effort="28"
      lower="-1.6"
      upper="1.6"
      effort="28"
      velocity="30" />
  </joint>
  <link
    name="UPPERARM_L">
    <inertial>
      <origin
        xyz="-0.00152 0.01042 0.1973"
        rpy="0 0 0" />
      <mass
        value="0.51544" />
      <inertia
        ixx="0.021671007"
        ixy="-1.03E-05"
        ixz="-0.000175798"
        iyy="0.021507692"
        iyz="0.001197139"
        izz="0.000365985" />
    </inertial>
    <visual>
      <origin
        xyz="0 0 0"
        rpy="0 0 0" />
      <geometry>
        <mesh
          filename="package://themis_description/meshes/UPPERARM_L.STL" />
      </geometry>
      <material
        name="">
        <color
          rgba="0.792156863 0.819607843 0.933333333 1" />
      </material>
    </visual>
    <collision>
      <origin
        xyz="0 0 0"
        rpy="0 0 0" />
      <geometry>
        <mesh
          filename="package://themis_description/meshes/UPPERARM_L.STL" />
      </geometry>
    </collision>
  </link>
  <joint
    name="SHOULDER_YAW_L"
    type="revolute">
    <origin
      xyz="0 0 0"
      rpy="3.141592653 -1.570796327 0" />
    <parent
      link="LOWERSHOULDER_L" />
    <child
      link="UPPERARM_L" />
    <axis
      xyz="0 0 1" />
    <limit
      command_effort="28"
      lower="-3.1416"
      upper="3.1416"
      effort="28"
      velocity="30" />
  </joint>
  <link
    name="ELBOW_L">
    <inertial>
      <origin
        xyz="0.05387 0.01441 -1.00E-05"
        rpy="0 0 0" />
      <mass
        value="0.37854" />
      <inertia
        ixx="0.000368777"
        ixy="0.000307949"
        ixz="-5.93E-07"
        iyy="0.00143067"
        iyz="2.39E-07"
        izz="0.001431848" />
    </inertial>
    <visual>
      <origin
        xyz="0 0 0"
        rpy="0 0 0" />
      <geometry>
        <mesh
          filename="package://themis_description/meshes/ELBOW_L.STL" />
      </geometry>
      <material
        name="">
        <color
          rgba="0.792156863 0.819607843 0.933333333 1" />
      </material>
    </visual>
    <collision>
      <origin
        xyz="0 0 0"
        rpy="0 0 0" />
      <geometry>
        <mesh
          filename="package://themis_description/meshes/ELBOW_L.STL" />
      </geometry>
    </collision>
  </link>
  <joint
    name="ELBOW_PITCH_L"
    type="revolute">
    <origin
      xyz="0 0.015 0.22495"
      rpy="3.141592653 -1.570796327 0" />
    <parent
      link="UPPERARM_L" />
    <child
      link="ELBOW_L" />
    <axis
      xyz="0 0 1" />
    <limit
      command_effort="28"
      lower="-3.1416"
      upper="3.1416"
      effort="28"
      velocity="30" />
  </joint>
  <link
    name="FOREARM_L">
    <inertial>
      <origin
        xyz="0.00164 2.00E-05 -0.01407"
        rpy="0 0 0" />
      <mass
        value="0.47694" />
      <inertia
        ixx="0.00068432"
        ixy="2.81E-07"
        ixz="-4.70E-06"
        iyy="0.00060081"
        iyz="-7.48E-07"
        izz="0.000265072" />
    </inertial>
    <visual>
      <origin
        xyz="0 0 0"
        rpy="0 0 0" />
      <geometry>
        <mesh
          filename="package://themis_description/meshes/FOREARM_L.STL" />
      </geometry>
      <material
        name="">
        <color
          rgba="0.792156863 0.819607843 0.933333333 1" />
      </material>
    </visual>
    <collision>
      <origin
        xyz="0 0 0"
        rpy="0 0 0" />
      <geometry>
        <mesh
          filename="package://themis_description/meshes/FOREARM_L.STL" />
      </geometry>
    </collision>
  </link>
  <joint
    name="ELBOW_YAW_L"
    type="revolute">
    <origin
      xyz="0.154950006 0.015 0"
      rpy="3.14133862 -1.570796312 0" />
    <parent
      link="ELBOW_L" />
    <child
      link="FOREARM_L" />
    <axis
      xyz="0 0 1" />
    <limit
      command_effort="28"
      lower="-3.1416"
      upper="3.1416"
      effort="28"
      velocity="30" />
  </joint>
  <link
    name="UPPERWRIST_L">
    <inertial>
      <origin
        xyz="0.05463 0.00013 7.00E-05"
        rpy="0 0 0" />
      <mass
        value="0.37004" />
      <inertia
        ixx="0.000277159"
        ixy="3.87E-06"
        ixz="2.13E-06"
        iyy="0.001412655"
        iyz="-5.78E-08"
        izz="0.001337475" />
    </inertial>
    <visual>
      <origin
        xyz="0 0 0"
        rpy="0 0 0" />
      <geometry>
        <mesh
          filename="package://themis_description/meshes/UPPERWRIST_L.STL" />
      </geometry>
      <material
        name="">
        <color
          rgba="0.792156863 0.819607843 0.933333333 1" />
      </material>
    </visual>
    <collision>
      <origin
        xyz="0 0 0"
        rpy="0 0 0" />
      <geometry>
        <mesh
          filename="package://themis_description/meshes/UPPERWRIST_L.STL" />
      </geometry>
    </collision>
  </link>
  <joint
    name="WRIST_PITCH_L"
    type="revolute">
    <origin
      xyz="0 0 0"
      rpy="3.141592653 -1.570796327 0" />
    <parent
      link="FOREARM_L" />
    <child
      link="UPPERWRIST_L" />
    <axis
      xyz="0 0 1" />
    <limit
      command_effort="28"
      lower="-3.1416"
      upper="3.1416"
      effort="28"
      velocity="30" />
  </joint>
  <link
    name="LOWERWRIST_L">
    <inertial>
      <origin
        xyz="0 -2.37E-06 0.00010824"
        rpy="0 0 0" />
      <mass
        value="0.42" />
      <inertia
        ixx="0.001"
        ixy="0"
        ixz="0"
        iyy="0.001"
        iyz="0"
        izz="0.001" />
    </inertial>
    <visual>
      <origin
        xyz="0 0 0"
        rpy="0 0 0" />
      <geometry>
        <mesh
          filename="package://themis_description/meshes/LOWERWRIST_L.STL" />
      </geometry>
      <material
        name="">
        <color
          rgba="0.792156863 0.819607843 0.933333333 1" />
      </material>
    </visual>
    <collision>
      <origin
        xyz="0 0 0"
        rpy="0 0 0" />
      <geometry>
        <mesh
          filename="package://themis_description/meshes/LOWERWRIST_L.STL" />
      </geometry>
    </collision>
  </link>
  <joint
    name="WRIST_YAW_L"
    type="revolute">
    <origin
      xyz="0 0 0"
      rpy="3.141592653 -1.570796327 0" />
    <parent
      link="UPPERWRIST_L" />
    <child
      link="LOWERWRIST_L" />
    <axis
      xyz="0 0 1" />
    <limit
      command_effort="28"
      lower="-3.1416"
      upper="3.1416"
      effort="28"
      velocity="30" />
  </joint>
  <link
    name="NECK">
    <inertial>
      <origin
        xyz="0 0.00017 -0.00489"
        rpy="0 0 0" />
      <mass
        value="0.34044" />
      <inertia
        ixx="0.000199"
        ixy="1.56E-05"
        ixz="-2.91E-05"
        iyy="0.000274"
        iyz="-2.51E-06"
        izz="0.000167" />
    </inertial>
    <visual>
      <origin
        xyz="0 0 0"
        rpy="0 0 0" />
      <geometry>
        <mesh
          filename="package://themis_description/meshes/NECK.STL" />
      </geometry>
      <material
        name="">
        <color
          rgba="0.792156863 0.819607843 0.933333333 1" />
      </material>
    </visual>
    <collision>
      <origin
        xyz="0 0 0"
        rpy="0 0 0" />
      <geometry>
        <mesh
          filename="package://themis_description/meshes/NECK.STL" />
      </geometry>
    </collision>
  </link>
  <joint
    name="HEAD_YAW"
    type="revolute">
    <origin
      xyz="-0.069373655 0 0.230835692"
      rpy="0 0 0" />
    <parent
      link="BASE_LINK" />
    <child
      link="NECK" />
    <axis
      xyz="0 0 1" />
    <limit
      command_effort="28"
      lower="-1.6"
      upper="1.6"
      effort="28"
      velocity="30" />
  </joint>
  <link
    name="HEAD">
    <inertial>
      <origin
        xyz="0.00094 0.0631 -1.00E-05"
        rpy="0 0 0" />
      <mass
        value="0.67367" />
      <inertia
        ixx="0.004633"
        ixy="9.34E-05"
        ixz="0.000261"
        iyy="0.003171"
        iyz="1.21E-06"
        izz="0.004426" />
    </inertial>
    <visual>
      <origin
        xyz="0 0 0"
        rpy="0 0 0" />
      <geometry>
        <mesh
          filename="package://themis_description/meshes/HEAD.STL" />
      </geometry>
      <material
        name="">
        <color
          rgba="0.792156863 0.819607843 0.933333333 1" />
      </material>
    </visual>
    <collision>
      <origin
        xyz="0 0 0"
        rpy="0 0 0" />
      <geometry>
        <mesh
          filename="package://themis_description/meshes/HEAD.STL" />
      </geometry>
    </collision>
  </link>
  <joint
    name="HEAD_PITCH"
    type="revolute">
    <origin
      xyz="0 0 0"
      rpy="1.570796327 0 0" />
    <parent
      link="NECK" />
    <child
      link="HEAD" />
    <axis
      xyz="0 0 1" />
    <limit
      command_effort="28"
      lower="-1.6"
      upper="1.6"
      effort="28"
      velocity="30" />
  </joint>
</robot>